Workbook

Sheet KhoiVTM
A1: No. | B1: DigiKey Part Number | C1: Manufacturer Product Number | D1: Description | E1: Link DigiKey | F1: Qty | G1: Price per Unit ($) | H1: Total Price ($) | I1: Total Price (VND) | J1: Value | K1: Unit | L1: Tolerance (%) | M1: Package | N1: Category | O1: status | P1: System | Q1: Note
A2: 1 | B2: AD9834BRUZ-REEL7TR-ND | C2: AD9834BRUZ-REEL7 | D2: IC DDS 50MHZ 10BIT 20TSSOP | E2: https://www.digikey.com/en/products/detail/analog-devices-inc/AD9834BRUZ-REEL7/994992 | F2: 4 | G2: 17.92 | H2: =G2*F2 -> 71.68 | I2: =H2*26190 -> 1877299.2 | J2: NaN | K2: N/A | L2: NaN | M2: 20-TSSOP | N2: IC | O2: Done | P2: EIM | S2: Total cost USDT | T2: =SUM($H:$H) -> 827.64275
A3: 2 | B3: 505-AD8302ARUZ-ND | C3: AD8302ARUZ | D3: IC RF DETECT 2.7GHZ 14TSSOP | E3: https://www.mouser.vn/ProductDetail/Analog-Devices/AD8302ARUZ-RL7?qs=%2FtpEQrCGXCxf7u2FSUHSPQ%3D%3D | F3: 4 | G3: 34.64 | H3: =G3*F3 -> 138.56 | I3: =H3*26190 -> 3628886.4 | J3: NaN | K3: N/A | L3: NaN | M3: 14-TSSOP | N3: IC | O3: Done | P3: EIM | S3: Tocal Cost VND | T3: =SUM($I:$I) -> 21615727
A4: 3 | B4: 497-14909-ND | C4: STM32F411RET6 | D4: IC MCU 32BIT 512KB FLASH 64LQFP | E4: https://www.digikey.com/en/products/detail/stmicroelectronics/STM32F411RET6/4935722 | F4: 2 | G4: 6.69 | H4: =G4*F4 -> 13.38 | I4: =H4*26190 -> 350422.2 | J4: NaN | K4: N/A | M4: 64-LQFP | N4: uC | O4: Done | P4: EIM | S4: Total Cost Taiwan | T4: =$T$2*31.63 -> 26178.34
A5: 4 | B5: 505-AD8130ARMZ-REELTR-ND | C5: AD8130ARMZ-REEL | D5: IC OPAMP DIFF 1 CIRCUIT 8MSOP | E5: https://www.digikey.com/en/products/detail/analog-devices-inc/AD8130ARMZ-REEL/994072 | F5: 6 | G5: 5.18 | H5: =G5*F5 -> 31.08 | I5: =H5*26190 -> 813985.2 | J5: NaN | K5: N/A | L5: NaN | M5: 8-TSSOP | N5: IC | O5: Done | P5: EIM
A6: 5 | B6: 541-3194-2-ND | C6: TNPW06036K80BEEA | D6: RES 6.8K OHM 0.1% 0.21W 0603 | E6: https://www.digikey.com/en/products/detail/vishay-dale/TNPW06036K80BEEA/1606862?s=N4IgTCBcDaICoDkAKB1ADANjQZgwaQA40AhAUVIEEQBdAXyA | F6: 25 | G6: 0.23 | H6: =G6*F6 -> 5.75 | I6: =H6*26190 -> 150592.5 | J6: =TRIM(LEFT(SUBSTITUTE(TRIM(SUBSTITUTE(SUBSTITUTE(D6,"RES",""),"SMD",""))," ",REPT(" ",100)),100)) -> 6.8K | K6: Ohm (Ω) | L6: =_xlfn.TEXTAFTER(_xlfn.TEXTBEFORE(D6, "%"), " ", -1) & "%" -> 0.1% | M6: =RIGHT(TRIM(D6), 4) -> 0603 | N6: Resistor | O6: Done | P6: EIM
A7: 6 | B7: 541-3049-2-ND | C7: TNPW0603200RBEEA | D7: RES 200 OHM 0.1% 0.21W 0603 | E7: https://www.digikey.com/en/products/detail/vishay-dale/TNPW0603200RBEEA/1606685?s=N4IgTCBcDaICoDkAKB1ADANjQZjGtASgEICiJAgiALoC%2BQA | F7: 25 | G7: 0.23 | H7: =G7*F7 -> 5.75 | I7: =H7*26190 -> 150592.5 | J7: =TRIM(LEFT(SUBSTITUTE(TRIM(SUBSTITUTE(SUBSTITUTE(D7,"RES",""),"SMD",""))," ",REPT(" ",100)),100)) -> 200 | K7: Ohm (Ω) | L7: =_xlfn.TEXTAFTER(_xlfn.TEXTBEFORE(D7, "%"), " ", -1) & "%" -> 0.1% | M7: =RIGHT(TRIM(D7), 4) -> 0603 | N7: Resistor | O7: Done | P7: EIM
A8: 7 | B8: 541-3634-2-ND | C8: TNPW0603280RBEEA | D8: RES 280 OHM 0.1% 0.21W 0603 | E8: https://www.digikey.com/en/products/detail/vishay-dale/tnpw0603280rbeea/1606702 | F8: 25 | G8: 0.23 | H8: =G8*F8 -> 5.75 | I8: =H8*26190 -> 150592.5 | J8: =TRIM(LEFT(SUBSTITUTE(TRIM(SUBSTITUTE(SUBSTITUTE(D8,"RES",""),"SMD",""))," ",REPT(" ",100)),100)) -> 280 | K8: Ohm (Ω) | L8: =_xlfn.TEXTAFTER(_xlfn.TEXTBEFORE(D8, "%"), " ", -1) & "%" -> 0.1% | M8: =RIGHT(TRIM(D8), 4) -> 0603 | N8: =IF(LEFT(D8,3)="RES", "Resistor", IF(LEFT(D8,3)="CAP", "Capacitor", "Other")) -> Resistor | O8: Done | P8: EIM
A9: 8 | B9: TNPW06031K00BEEA | C9: TNP1.00KAATR-ND | D9: RES 1K OHM 0.1% 0.21W 0603 | E9: https://www.digikey.com/en/products/detail/vishay-dale/TNPW06031K00BEEA/1606767?s=N4IgTCBcDaICoDkAKBGAdABgwaQIK7gCUBaBAERAF0BfIA | F9: 25 | G9: 0.23 | H9: =G9*F9 -> 5.75 | I9: =H9*26190 -> 150592.5 | J9: =TRIM(LEFT(SUBSTITUTE(TRIM(SUBSTITUTE(SUBSTITUTE(D9,"RES",""),"SMD",""))," ",REPT(" ",100)),100)) -> 1K | K9: Ohm (Ω) | L9: =_xlfn.TEXTAFTER(_xlfn.TEXTBEFORE(D9, "%"), " ", -1) & "%" -> 0.1% | M9: =RIGHT(TRIM(D9), 4) -> 0603 | N9: =IF(LEFT(D9,3)="RES", "Resistor", IF(LEFT(D9,3)="CAP", "Capacitor", "Other")) -> Resistor | O9: Done | P9: EIM
A10: 9 | B10: 311-22.0HRTR-ND | C10: RC0603FR-0722RL | D10: RES 22 OHM 1% 1/10W 0603 | E10: https://www.digikey.com/en/products/detail/yageo/RC0603FR-0722RL/727055?s=N4IgTCBcDaIEoGEAMA2JBmAYnAtEg7GGHADIgC6AvkA | F10: 25 | G10: 0.1 | H10: =G10*F10 -> 2.5 | I10: =H10*26190 -> 65475 | J10: =TRIM(LEFT(SUBSTITUTE(TRIM(SUBSTITUTE(SUBSTITUTE(D10,"RES",""),"SMD",""))," ",REPT(" ",100)),100)) -> 22 | K10: Ohm (Ω) | L10: =_xlfn.TEXTAFTER(_xlfn.TEXTBEFORE(D10, "%"), " ", -1) & "%" -> 1% | M10: =RIGHT(TRIM(D10), 4) -> 0603 | N10: =IF(LEFT(D10,3)="RES", "Resistor", IF(LEFT(D10,3)="CAP", "Capacitor", "Other")) -> Resistor | O10: Done | P10: EIM
A11: 10 | B11: RC0603JR-070RL | C11: RC0603JR-070RL | D11: RES 0 OHM JUMPER 1/10W 0603 | E11: https://www.digikey.com/en/products/detail/yageo/RC0603JR-070RL/726675?s=N4IgTCBcDaIEoGEAMA2JBmAUnAtEg7EnADIgC6AvkA | F11: 25 | G11: 0.1 | H11: =G11*F11 -> 2.5 | I11: =H11*26190 -> 65475 | J11: =TRIM(LEFT(SUBSTITUTE(TRIM(SUBSTITUTE(SUBSTITUTE(D11,"RES",""),"SMD",""))," ",REPT(" ",100)),100)) -> 0 | K11: Ohm (Ω) | L11: N/A | M11: =RIGHT(TRIM(D11), 4) -> 0603 | N11: =IF(LEFT(D11,3)="RES", "Resistor", IF(LEFT(D11,3)="CAP", "Capacitor", "Other")) -> Resistor | O11: Done | P11: EIM
A12: 11 | B12: 541-2030-2-ND | C12: TNPW0603499RBEEA | D12: RES 499 OHM 0.1% 0.21W 0603 | E12: https://www.digikey.com/en/products/detail/vishay-dale/tnpw0603499rbeea/1606732 | F12: 25 | G12: 0.23 | H12: =G12*F12 -> 5.75 | I12: =H12*26190 -> 150592.5 | J12: =TRIM(LEFT(SUBSTITUTE(TRIM(SUBSTITUTE(SUBSTITUTE(D12,"RES",""),"SMD",""))," ",REPT(" ",100)),100)) -> 499 | K12: Ohm (Ω) | L12: =_xlfn.TEXTAFTER(_xlfn.TEXTBEFORE(D12, "%"), " ", -1) & "%" -> 0.1% | M12: =RIGHT(TRIM(D12), 4) -> 0603 | N12: =IF(LEFT(D12,3)="RES", "Resistor", IF(LEFT(D12,3)="CAP", "Capacitor", "Other")) -> Resistor | O12: Done | P12: EIM
A13: 12 | B13: TNPW06031K78BEEA | C13: 541-TNPW06031K78BEEATR-ND | D13: RES 1.78K OHM 0.1% 0.21W 0603 | E13: https://www.digikey.cn/en/products/detail/vishay-dale/tnpw06031k78beea/1606793 | F13: 25 | G13: 0.23 | H13: =G13*F13 -> 5.75 | I13: =H13*26190 -> 150592.5 | J13: =TRIM(LEFT(SUBSTITUTE(TRIM(SUBSTITUTE(SUBSTITUTE(D13,"RES",""),"SMD",""))," ",REPT(" ",100)),100)) -> 1.78K | K13: Ohm (Ω) | L13: =_xlfn.TEXTAFTER(_xlfn.TEXTBEFORE(D13, "%"), " ", -1) & "%" -> 0.1% | M13: =RIGHT(TRIM(D13), 4) -> 0603 | N13: =IF(LEFT(D13,3)="RES", "Resistor", IF(LEFT(D13,3)="CAP", "Capacitor", "Other")) -> Resistor | O13: Done | P13: EIM
A14: 13 | B14: 311-510HRTR-ND | C14: RC0603FR-07510RL | D14: RES 510 OHM 1% 1/10W 0603 | E14: https://www.digikey.com/en/products/detail/yageo/rc0603fr-07510rl/727285 | F14: 25 | G14: 0.1 | H14: =G14*F14 -> 2.5 | I14: =H14*26190 -> 65475 | J14: =TRIM(LEFT(SUBSTITUTE(TRIM(SUBSTITUTE(SUBSTITUTE(D14,"RES",""),"SMD",""))," ",REPT(" ",100)),100)) -> 510 | K14: Ohm (Ω) | L14: =_xlfn.TEXTAFTER(_xlfn.TEXTBEFORE(D14, "%"), " ", -1) & "%" -> 1% | M14: =RIGHT(TRIM(D14), 4) -> 0603 | N14: =IF(LEFT(D14,3)="RES", "Resistor", IF(LEFT(D14,3)="CAP", "Capacitor", "Other")) -> Resistor | O14: Done | P14: EIM
A15: 14 | B15: 2266-RC0603FR-072K67LTR-ND | C15: RC0603FR-072K67L | D15: RES 2.67K OHM 1% 0.1W, 1/10W 0603 | E15: https://www.digikey.com/en/products/detail/yageo-america/rc0603fr-072k67l/22283163 | F15: 25 | G15: 0.002 | H15: =G15*F15 -> 0.05 | I15: =H15*26190 -> 1309.5 | J15: =TRIM(LEFT(SUBSTITUTE(TRIM(SUBSTITUTE(SUBSTITUTE(D15,"RES",""),"SMD",""))," ",REPT(" ",100)),100)) -> 2.67K | K15: Ohm (Ω) | L15: =_xlfn.TEXTAFTER(_xlfn.TEXTBEFORE(D15, "%"), " ", -1) & "%" -> 1% | M15: =RIGHT(TRIM(D15), 4) -> 0603 | N15: =IF(LEFT(D15,3)="RES", "Resistor", IF(LEFT(D15,3)="CAP", "Capacitor", "Other")) -> Resistor | O15: Done | P15: EIM
A16: 15 | B16: 311-51.0HRTR-ND | C16: RC0603FR-0751RL | D16: RES 51 OHM 1% 1/10W 0603 | E16: https://www.digikey.com/en/products/detail/yageo/rc0603fr-0751rl/727281 | F16: 25 | G16: 0.1 | H16: =G16*F16 -> 2.5 | I16: =H16*26190 -> 65475 | J16: =TRIM(LEFT(SUBSTITUTE(TRIM(SUBSTITUTE(SUBSTITUTE(D16,"RES",""),"SMD",""))," ",REPT(" ",100)),100)) -> 51 | K16: Ohm (Ω) | L16: =_xlfn.TEXTAFTER(_xlfn.TEXTBEFORE(D16, "%"), " ", -1) & "%" -> 1% | M16: =RIGHT(TRIM(D16), 4) -> 0603 | N16: =IF(LEFT(D16,3)="RES", "Resistor", IF(LEFT(D16,3)="CAP", "Capacitor", "Other")) -> Resistor | O16: Done | P16: EIM
A17: 16 | B17: 311-10.0KHRTR-ND | C17: RC0603FR-0710KL | D17: RES 10K OHM 1% 1/10W 0603 | E17: https://www.digikey.com/en/products/detail/yageo/rc0603fr-0710kl/726880 | F17: 25 | G17: 0.1 | H17: =G17*F17 -> 2.5 | I17: =H17*26190 -> 65475 | J17: =TRIM(LEFT(SUBSTITUTE(TRIM(SUBSTITUTE(SUBSTITUTE(D17,"RES",""),"SMD",""))," ",REPT(" ",100)),100)) -> 10K | K17: Ohm (Ω) | L17: =_xlfn.TEXTAFTER(_xlfn.TEXTBEFORE(D17, "%"), " ", -1) & "%" -> 1% | M17: =RIGHT(TRIM(D17), 4) -> 0603 | N17: =IF(LEFT(D17,3)="RES", "Resistor", IF(LEFT(D17,3)="CAP", "Capacitor", "Other")) -> Resistor | O17: Done | P17: EIM
A18: 17 | B18: TNP10.0AATR-ND | C18: TNPW060310R0BEEA | D18: RES 10 OHM 0.1% 0.21W 0603 | E18: https://www.digikey.com/en/products/detail/vishay-dale/tnpw060310r0beea/1606539 | F18: 25 | G18: 0.31 | H18: =G18*F18 -> 7.75 | I18: =H18*26190 -> 202972.5 | J18: =TRIM(LEFT(SUBSTITUTE(TRIM(SUBSTITUTE(SUBSTITUTE(D18,"RES",""),"SMD",""))," ",REPT(" ",100)),100)) -> 10 | K18: Ohm (Ω) | L18: =_xlfn.TEXTAFTER(_xlfn.TEXTBEFORE(D18, "%"), " ", -1) & "%" -> 0.1% | M18: =RIGHT(TRIM(D18), 4) -> 0603 | N18: =IF(LEFT(D18,3)="RES", "Resistor", IF(LEFT(D18,3)="CAP", "Capacitor", "Other")) -> Resistor | O18: Done | P18: EIM
A19: 18 | B19: 490-1410-2-ND | C19: GRM1885C1H200JA01D | D19: CAP CER 20PF 50V C0G/NP0 0603 | E19: https://www.digikey.com/en/products/detail/murata-electronics/GRM1885C1H200JA01D/586920 | F19: 25 | G19: 0.12 | H19: =G19*F19 -> 3 | I19: =H19*26190 -> 78570 | J19: =_xlfn.TEXTBEFORE(_xlfn.TEXTAFTER(D19, "CER "), "F") -> 20P | K19: Farad (F) | M19: =RIGHT(TRIM(D19), 4) -> 0603 | N19: =IF(LEFT(D19,3)="RES", "Resistor", IF(LEFT(D19,3)="CAP", "Capacitor", "Other")) -> Capacitor | O19: Done | P19: EIM
A20: 19 | B20: 490-10700-2-ND | C20: GRM155R71H104KE14D | D20: CAP CER 0.1UF 50V X7R 0603 | E20: https://www.digikey.com/en/products/detail/kemet/C0603C104K5RACTU/1465594 | F20: 25 | G20: 0.08 | H20: =G20*F20 -> 2 | I20: =H20*26190 -> 52380 | J20: =_xlfn.TEXTBEFORE(_xlfn.TEXTAFTER(D20, "CER "), "F") -> 0.1U | K20: Farad (F) | M20: =RIGHT(TRIM(D20), 4) -> 0603 | N20: =IF(LEFT(D20,3)="RES", "Resistor", IF(LEFT(D20,3)="CAP", "Capacitor", "Other")) -> Capacitor | O20: Done | P20: EIM
A21: 20 | B21: 399-C0603C105K3RACTUTR-ND | C21: C0603C105K3RACTU | D21: CAP CER 1UF 25V X7R 0603 | E21: https://www.digikey.com/en/products/detail/kemet/C0603C105K3RACTU/3317410 | F21: 25 | G21: 0.41 | H21: =G21*F21 -> 10.25 | I21: =H21*26190 -> 268447.5 | J21: =_xlfn.TEXTBEFORE(_xlfn.TEXTAFTER(D21, "CER "), "F") -> 1U | K21: Farad (F) | M21: =RIGHT(TRIM(D21), 4) -> 0603 | N21: =IF(LEFT(D21,3)="RES", "Resistor", IF(LEFT(D21,3)="CAP", "Capacitor", "Other")) -> Capacitor | O21: Done | P21: EIM
A22: 21 | B22: GRM1555C1H1R0WA01J-ND | C22: GRM1555C1H1R0WA01J | D22: CAP CER 1PF 50V C0G/NP0 0402 | E22: https://www.digikey.com/en/products/detail/murata-electronics/grm1555c1h1r0wa01j/4904825 | F22: 25 | G22: 0.0148 | H22: =G22*F22 -> 0.37 | I22: =H22*26190 -> 9690.3 | J22: =_xlfn.TEXTBEFORE(_xlfn.TEXTAFTER(D22, "CER "), "F") -> 1P | K22: Farad (F) | M22: =RIGHT(TRIM(D22), 4) -> 0402 | N22: =IF(LEFT(D22,3)="RES", "Resistor", IF(LEFT(D22,3)="CAP", "Capacitor", "Other")) -> Capacitor | O22: Done | P22: EIM
A23: 22 | B23: 311-1873-2-ND | C23: CC0805KKX5R9BB225 | D23: CAP CER 2.2UF 50V X5R 0805 | E23: https://www.digikey.com/en/products/detail/yageo/CC0805KKX5R9BB225/5195775 | F23: 25 | G23: 0.025 | H23: =G23*F23 -> 0.625 | I23: =H23*26190 -> 16368.75 | J23: =_xlfn.TEXTBEFORE(_xlfn.TEXTAFTER(D23, "CER "), "F") -> 2.2U | K23: Farad (F) | M23: =RIGHT(TRIM(D23), 4) -> 0805 | N23: =IF(LEFT(D23,3)="RES", "Resistor", IF(LEFT(D23,3)="CAP", "Capacitor", "Other")) -> Capacitor | O23: Done | P23: EIM
A24: 23 | B24: 490-16772-2-ND | C24: GRM1885C1H181JA01J | D24: CAP CER 180PF 50V C0G/NP0 0603 | E24: https://www.digikey.com/en/products/detail/murata-electronics/grm1885c1h181ja01j/2611094 | F24: 25 | G24: 0.01822 | H24: =G24*F24 -> 0.4555 | I24: =H24*26190 -> 11929.545 | J24: =_xlfn.TEXTBEFORE(_xlfn.TEXTAFTER(D24, "CER "), "F") -> 180P | K24: Farad (F) | M24: =RIGHT(TRIM(D24), 4) -> 0603 | N24: =IF(LEFT(D24,3)="RES", "Resistor", IF(LEFT(D24,3)="CAP", "Capacitor", "Other")) -> Capacitor | O24: Done | P24: EIM
A25: 24 | B25: 490-1438-2-ND | C25: GRM1885C1H301JA01D | D25: CAP CER 300PF 50V C0G/NP0 0603 | E25: https://www.digikey.com/en/products/detail/murata-electronics/grm1885c1h301ja01d/586964 | F25: 25 | G25: 0.13 | H25: =G25*F25 -> 3.25 | I25: =H25*26190 -> 85117.5 | J25: =_xlfn.TEXTBEFORE(_xlfn.TEXTAFTER(D25, "CER "), "F") -> 300P | K25: Farad (F) | M25: =RIGHT(TRIM(D25), 4) -> 0603 | N25: =IF(LEFT(D25,3)="RES", "Resistor", IF(LEFT(D25,3)="CAP", "Capacitor", "Other")) -> Capacitor | O25: Done | P25: EIM
A26: 25 | B26: 490-16776-2-ND | C26: GRM1885C1H331JA01J | D26: CAP CER 330PF 50V C0G/NP0 0603 | E26: https://www.digikey.com/en/products/detail/murata-electronics/grm1885c1h331ja01j/2611160 | F26: 25 | G26: 0.11 | H26: =G26*F26 -> 2.75 | I26: =H26*26190 -> 72022.5 | J26: =_xlfn.TEXTBEFORE(_xlfn.TEXTAFTER(D26, "CER "), "F") -> 330P | K26: Farad (F) | M26: =RIGHT(TRIM(D26), 4) -> 0603 | N26: =IF(LEFT(D26,3)="RES", "Resistor", IF(LEFT(D26,3)="CAP", "Capacitor", "Other")) -> Capacitor | O26: Done | P26: EIM
A27: 26 | B27: 490-11457-2-ND | C27: GRM1885C1H271JA01J | D27: CAP CER 270PF 50V C0G/NP0 0603 | E27: https://www.digikey.com/en/products/detail/murata-electronics/grm1885c1h271ja01j/2611130 | F27: 25 | G27: 0.02501 | H27: =G27*F27 -> 0.62525 | I27: =H27*26190 -> 16375.297 | J27: =_xlfn.TEXTBEFORE(_xlfn.TEXTAFTER(D27, "CER "), "F") -> 270P | K27: Farad (F) | M27: =RIGHT(TRIM(D27), 4) -> 0603 | N27: =IF(LEFT(D27,3)="RES", "Resistor", IF(LEFT(D27,3)="CAP", "Capacitor", "Other")) -> Capacitor | O27: Done | P27: EIM
A28: 27 | B28: 490-1419-2-ND | C28: GRM1885C1H470JA01D | D28: CAP CER 47PF 50V C0G/NP0 0603 | E28: https://www.digikey.com/en/products/detail/murata-electronics/GRM1885C1H470JA01D/586904 | F28: 25 | G28: 0.12 | H28: =G28*F28 -> 3 | I28: =H28*26190 -> 78570 | J28: =_xlfn.TEXTBEFORE(_xlfn.TEXTAFTER(D28, "CER "), "F") -> 47P | K28: Farad (F) | M28: =RIGHT(TRIM(D28), 4) -> 0603 | N28: =IF(LEFT(D28,3)="RES", "Resistor", IF(LEFT(D28,3)="CAP", "Capacitor", "Other")) -> Capacitor | O28: Done | P28: EIM
A29: 28 | B29: 490-3285-2-ND | C29: GRM188R72A104KA35D | D29: CAP CER 0.1UF 100V X7R 0603 | E29: https://www.digikey.com/en/products/detail/murata-electronics/GRM188R72A104KA35D/702826 | F29: 25 | G29: 0.14 | H29: =G29*F29 -> 3.5 | I29: =H29*26190 -> 91665 | J29: =_xlfn.TEXTBEFORE(_xlfn.TEXTAFTER(D29, "CER "), "F") -> 0.1U | K29: Farad (F) | M29: =RIGHT(TRIM(D29), 4) -> 0603 | N29: =IF(LEFT(D29,3)="RES", "Resistor", IF(LEFT(D29,3)="CAP", "Capacitor", "Other")) -> Capacitor | O29: Done | P29: EIM
A30: 29 | B30: 490-GRM188R72A103KA01DTR-ND | C30: GRM188R72A103KA01D | D30: CAP CER 10000PF 100V X7R 0603 | E30: https://www.digikey.com/en/products/detail/murata-electronics/GRM188R72A103KA01D/3845635 | F30: 25 | G30: 0.1 | H30: =G30*F30 -> 2.5 | I30: =H30*26190 -> 65475 | J30: =_xlfn.TEXTBEFORE(_xlfn.TEXTAFTER(D30, "CER "), "F") -> 10000P | K30: Farad (F) | M30: =RIGHT(TRIM(D30), 4) -> 0603 | N30: =IF(LEFT(D30,3)="RES", "Resistor", IF(LEFT(D30,3)="CAP", "Capacitor", "Other")) -> Capacitor | O30: Done | P30: EIM
A31: 30 | B31: P49.9HTR-ND | C31: ERJ-3EKF49R9V | D31: RES SMD 49.9 OHM 1% 1/10W 0603 | E31: ERJ-3EKF49R9V Panasonic Electronic Components | Resistors | DigiKey | F31: 25 | G31: 0.1 | H31: =G31*F31 -> 2.5 | I31: =H31*26190 -> 65475 | J31: =TRIM(LEFT(SUBSTITUTE(TRIM(SUBSTITUTE(SUBSTITUTE(D31,"RES",""),"SMD",""))," ",REPT(" ",100)),100)) -> 49.9 | K31: Ohm (Ω) | L31: =_xlfn.TEXTAFTER(_xlfn.TEXTBEFORE(D31, "%"), " ", -1) & "%" -> 1% | M31: =RIGHT(TRIM(D31), 4) -> 0603 | N31: =IF(LEFT(D31,3)="RES", "Resistor", IF(LEFT(D31,3)="CAP", "Capacitor", "Other")) -> Resistor | O31: Done | P31: EIM
A32: 31 | B32: 505-AD8014ARZ-ND | C32: AD8014ARZ | D32: IC OPAMP CFA 1 CIRCUIT 8SOIC | E32: https://www.digikey.com/en/products/detail/analog-devices-inc/ad8014arz/620459 | F32: 4 | G32: 4.59 | H32: =G32*F32 -> 18.36 | I32: =H32*26190 -> 480848.4 | J32: NaN | K32: N/A | L32: NaN | M32: 8SOIC | N32: IC | O32: Done | P32: EIM
A33: 32 | B33: 490-1181-1-ND | C33: LQW18ANR27J00D | D33: FIXED IND 270NH 0603 (Murata LQW18, high-Q) | E33: https://www.digikey.com/en/products/detail/murata-electronics/LQW18ANR27J00D/584389 | F33: 25 | G33: 0.11 | H33: =G33*F33 -> 2.75 | I33: =H33*26190 -> 72022.5 | J33: 270n | K33: Henry (H) | M33: 0603 | N33: Inductor | O33: Done | P33: EIM
A34: 33 | B34: 490-1183-1-ND | C34: LQW18ANR39J00D | D34: FIXED IND 390NH 0603 (Murata LQW18, high-Q) | E34: https://www.digikey.com/en/products/detail/murata-electronics/LQW18ANR39J00D/584391 | F34: 25 | G34: 0.11 | H34: =G34*F34 -> 2.75 | I34: =H34*26190 -> 72022.5 | J34: 390n | K34: Henry (H) | M34: 0603 | N34: Inductor | O34: Done | P34: EIM
A35: 34 | B35: 490-1184-1-ND | C35: LQW18ANR47J00D | D35: FIXED IND 470NH 0603 (Murata LQW18, high-Q) | E35: https://www.digikey.com/en/products/detail/murata-electronics/LQW18ANR47J00D/584392 | F35: 25 | G35: 0.11 | H35: =G35*F35 -> 2.75 | I35: =H35*26190 -> 72022.5 | J35: 470n | K35: Henry (H) | M35: 0603 | N35: Inductor | O35: Done | P35: EIM
A36: 35 | B36: 535-11201-1-ND | C36: ASDMB-75.000MHZ-LY-T | D36: MEMS OSC XO 75.0000MHZ LVCMOS (AD9834 MCLK) | E36: https://www.digikey.com/en/products/detail/abracon-llc/ASDMB-75-000MHZ-LY-T/2624314 | F36: 4 | G36: 3.85 | H36: =G36*F36 -> 15.4 | I36: =H36*26190 -> 403326 | J36: 75M | K36: Hertz (Hz) | M36: 4-SMD | N36: Ocsillator | O36: Done | P36: EIM
A37: 36 | B37: 296-50411-1-ND | C37: TLV75533PDBVR | D37: IC REG LINEAR 3.3V 500MA | E37: https://www.digikey.com/en/products/detail/texas-instruments/TLV75533PDBVR/9356541 | F37: 10 | G37: 0.25 | H37: =G37*F37 -> 2.5 | I37: =H37*26190 -> 65475 | J37: NaN | K37: N/A | L37: NaN | M37: SOT-23-5 | N37: IC-Power | O37: Done | P37: EIM
A38: 37 | B38: F3733CT-ND | C38: 1206L050/15YR | D38: PTC RESET FUSE 15V 500MA 1206 (input protection) | E38: https://www.digikey.com/en/products/detail/littelfuse-inc/1206L050-15YR/1211396 | F38: 10 | G38: 0.426 | H38: =G38*F38 -> 4.26 | I38: =H38*26190 -> 111569.4 | J38: NaN | K38: N/A | M38: 1206 | N38: FUSE | O38: Done | P38: EIM
A39: 38 | B39: 4878-SMF5.0ACT-ND | C39: SMF5.0A | D39: TVS DIODE 5VWM 9.2VC SOD-123F (5V rail surge/ESD) | E39: https://www.digikey.com/en/products/detail/diotec-semiconductor/SMF5-0A/13163545 | F39: 10 | G39: 0.25 | H39: =G39*F39 -> 2.5 | I39: =H39*26190 -> 65475 | M39: SOD-123F | N39: Diode | O39: Done | P39: EIM
A40: 39 | B40: 296-40695-1-ND | C40: TPD2E2U06QDBZRQ1 | D40: TVS DIODE 5.5VWM 12.4VC SOT23-3 | E40: https://www.digikey.com/en/products/detail/texas-instruments/TPD2E2U06QDBZRQ1/5056067 | F40: 10 | G40: 0.422 | H40: =G40*F40 -> 4.22 | I40: =H40*26190 -> 110521.8 | N40: Diode | O40: Remove | P40: EIM
...

Sheet EIM_Tracker
A1: No. (1st sheet) | B1: MPN | C1: Description | D1: Value | E1: Package | F1: Qty Ordered | G1: Qty Required | H1: Qty Used | I1: Remaining (= Ordered − Used) | J1: Category | K1: Status | L1: Remarks / Notes | N1: Validate with order | O1: Validate with schematic
A2: =KhoiVTM!A2 -> 1 | B2: =KhoiVTM!C2 -> AD9834BRUZ-REEL7 | C2: =KhoiVTM!D2 -> IC DDS 50MHZ 10BIT 20TSSOP | D2: — | E2: 20-TSSOP | F2: =KhoiVTM!F2 -> 4 | G2: =Kicad_Extract!D62 -> 1 | H2: 0 | I2: =F2-H2 -> 4 | J2: =IF(LEFT(C2,3)="RES", "Resistor", IF(LEFT(C2,3)="CAP", "Capacitor", "Other")) -> Other | K2: Done | N2: =IFERROR(IF(ISERROR(MATCH(B2,KhoiVTM!$C:$C,0)),"Not Found",IF((EXACT(C2,IFERROR(INDEX(KhoiVTM!$D:$D,MATCH(B2,KhoiVTM!$C:$C,0)),"__NA__"))*1)+(IFERROR(F2=INDEX(KhoiVTM!$F:$F,MATCH(B2,KhoiVTM!$C:$C,0)),FALSE())*1)+(IFERROR(OR(AND(OR(D2="—",D2=""),OR(TEXT(INDEX(KhoiVTM!$J:$J,MATCH(B2,KhoiVTM!$C:$C,0)),"@")="",TEXT(INDEX(KhoiVTM!$J:$J,MATCH(B2,KhoiVTM!$C:$C,0)),"@")="—")),EXACT(TEXT(D2,"@"),TEXT(INDEX(KhoiVTM!$J:$J,MATCH(B2,KhoiVTM!$C:$C,0)),"@"))),FALSE())*1)+(IFERROR(OR(AND(OR(E2="—",E2=""),OR(TEXT(INDEX(KhoiVTM!$M:$M,MATCH(B2,KhoiVTM!$C:$C,0)),"@")="",TEXT(INDEX(KhoiVTM!$M:$M,MATCH(B2,KhoiVTM!$C:$C,0)),"@")="—")),EXACT(TEXT(E2,"@"),TEXT(INDEX(KhoiVTM!$M:$M,MATCH(B2,KhoiVTM!$C:$C,0)),"@"))),FALSE())*1)=4,"Match",IF((EXACT(C2,IFERROR(INDEX(KhoiVTM!$D:$D,MATCH(B2,KhoiVTM!$C:$C,0)),"__NA__"))*1)+(IFERROR(F2=INDEX(KhoiVTM!$F:$F,MATCH(B2,KhoiVTM!$C:$C,0)),FALSE())*1)+(IFERROR(OR(AND(OR(D2="—",D2=""),OR(TEXT(INDEX(KhoiVTM!$J:$J,MATCH(B2,KhoiVTM!$C:$C,0)),"@")="",TEXT(INDEX(KhoiVTM!$J:$J,MATCH(B2,KhoiVTM!$C:$C,0)),"@")="—")),EXACT(TEXT(D2,"@"),TEXT(INDEX(KhoiVTM!$J:$J,MATCH(B2,KhoiVTM!$C:$C,0)),"@"))),FALSE())*1)+(IFERROR(OR(AND(OR(E2="—",E2=""),OR(TEXT(INDEX(KhoiVTM!$M:$M,MATCH(B2,KhoiVTM!$C:$C,0)),"@")="",TEXT(INDEX(KhoiVTM!$M:$M,MATCH(B2,KhoiVTM!$C:$C,0)),"@")="—")),EXACT(TEXT(E2,"@"),TEXT(INDEX(KhoiVTM!$M:$M,MATCH(B2,KhoiVTM!$C:$C,0)),"@"))),FALSE())*1)>=3,"Partial","Mismatch"))),"Not Found") -> Partial
A3: =KhoiVTM!A3 -> 2 | B3: =KhoiVTM!C3 -> AD8302ARUZ | C3: =KhoiVTM!D3 -> IC RF DETECT 2.7GHZ 14TSSOP | D3: — | E3: 14-TSSOP | F3: =KhoiVTM!F3 -> 4 | G3: 1 | H3: 0 | I3: =F3-H3 -> 4 | J3: =IF(LEFT(C3,3)="RES", "Resistor", IF(LEFT(C3,3)="CAP", "Capacitor", "Other")) -> Other | K3: Done | N3: =IFERROR(IF(ISERROR(MATCH(B3,KhoiVTM!$C:$C,0)),"Not Found",IF((EXACT(C3,IFERROR(INDEX(KhoiVTM!$D:$D,MATCH(B3,KhoiVTM!$C:$C,0)),"__NA__"))*1)+(IFERROR(F3=INDEX(KhoiVTM!$F:$F,MATCH(B3,KhoiVTM!$C:$C,0)),FALSE())*1)+(IFERROR(OR(AND(OR(D3="—",D3=""),OR(TEXT(INDEX(KhoiVTM!$J:$J,MATCH(B3,KhoiVTM!$C:$C,0)),"@")="",TEXT(INDEX(KhoiVTM!$J:$J,MATCH(B3,KhoiVTM!$C:$C,0)),"@")="—")),EXACT(TEXT(D3,"@"),TEXT(INDEX(KhoiVTM!$J:$J,MATCH(B3,KhoiVTM!$C:$C,0)),"@"))),FALSE())*1)+(IFERROR(OR(AND(OR(E3="—",E3=""),OR(TEXT(INDEX(KhoiVTM!$M:$M,MATCH(B3,KhoiVTM!$C:$C,0)),"@")="",TEXT(INDEX(KhoiVTM!$M:$M,MATCH(B3,KhoiVTM!$C:$C,0)),"@")="—")),EXACT(TEXT(E3,"@"),TEXT(INDEX(KhoiVTM!$M:$M,MATCH(B3,KhoiVTM!$C:$C,0)),"@"))),FALSE())*1)=4,"Match",IF((EXACT(C3,IFERROR(INDEX(KhoiVTM!$D:$D,MATCH(B3,KhoiVTM!$C:$C,0)),"__NA__"))*1)+(IFERROR(F3=INDEX(KhoiVTM!$F:$F,MATCH(B3,KhoiVTM!$C:$C,0)),FALSE())*1)+(IFERROR(OR(AND(OR(D3="—",D3=""),OR(TEXT(INDEX(KhoiVTM!$J:$J,MATCH(B3,KhoiVTM!$C:$C,0)),"@")="",TEXT(INDEX(KhoiVTM!$J:$J,MATCH(B3,KhoiVTM!$C:$C,0)),"@")="—")),EXACT(TEXT(D3,"@"),TEXT(INDEX(KhoiVTM!$J:$J,MATCH(B3,KhoiVTM!$C:$C,0)),"@"))),FALSE())*1)+(IFERROR(OR(AND(OR(E3="—",E3=""),OR(TEXT(INDEX(KhoiVTM!$M:$M,MATCH(B3,KhoiVTM!$C:$C,0)),"@")="",TEXT(INDEX(KhoiVTM!$M:$M,MATCH(B3,KhoiVTM!$C:$C,0)),"@")="—")),EXACT(TEXT(E3,"@"),TEXT(INDEX(KhoiVTM!$M:$M,MATCH(B3,KhoiVTM!$C:$C,0)),"@"))),FALSE())*1)>=3,"Partial","Mismatch"))),"Not Found") -> Partial
A4: =KhoiVTM!A4 -> 3 | B4: =KhoiVTM!C4 -> STM32F411RET6 | C4: =KhoiVTM!D4 -> IC MCU 32BIT 512KB FLASH 64LQFP | D4: — | E4: 64-LQFP | F4: =KhoiVTM!F4 -> 2 | G4: 0 | H4: 0 | I4: =F4-H4 -> 2 | J4: =IF(LEFT(C4,3)="RES", "Resistor", IF(LEFT(C4,3)="CAP", "Capacitor", "Other")) -> Other | K4: Done | N4: =IFERROR(IF(ISERROR(MATCH(B4,KhoiVTM!$C:$C,0)),"Not Found",IF((EXACT(C4,IFERROR(INDEX(KhoiVTM!$D:$D,MATCH(B4,KhoiVTM!$C:$C,0)),"__NA__"))*1)+(IFERROR(F4=INDEX(KhoiVTM!$F:$F,MATCH(B4,KhoiVTM!$C:$C,0)),FALSE())*1)+(IFERROR(OR(AND(OR(D4="—",D4=""),OR(TEXT(INDEX(KhoiVTM!$J:$J,MATCH(B4,KhoiVTM!$C:$C,0)),"@")="",TEXT(INDEX(KhoiVTM!$J:$J,MATCH(B4,KhoiVTM!$C:$C,0)),"@")="—")),EXACT(TEXT(D4,"@"),TEXT(INDEX(KhoiVTM!$J:$J,MATCH(B4,KhoiVTM!$C:$C,0)),"@"))),FALSE())*1)+(IFERROR(OR(AND(OR(E4="—",E4=""),OR(TEXT(INDEX(KhoiVTM!$M:$M,MATCH(B4,KhoiVTM!$C:$C,0)),"@")="",TEXT(INDEX(KhoiVTM!$M:$M,MATCH(B4,KhoiVTM!$C:$C,0)),"@")="—")),EXACT(TEXT(E4,"@"),TEXT(INDEX(KhoiVTM!$M:$M,MATCH(B4,KhoiVTM!$C:$C,0)),"@"))),FALSE())*1)=4,"Match",IF((EXACT(C4,IFERROR(INDEX(KhoiVTM!$D:$D,MATCH(B4,KhoiVTM!$C:$C,0)),"__NA__"))*1)+(IFERROR(F4=INDEX(KhoiVTM!$F:$F,MATCH(B4,KhoiVTM!$C:$C,0)),FALSE())*1)+(IFERROR(OR(AND(OR(D4="—",D4=""),OR(TEXT(INDEX(KhoiVTM!$J:$J,MATCH(B4,KhoiVTM!$C:$C,0)),"@")="",TEXT(INDEX(KhoiVTM!$J:$J,MATCH(B4,KhoiVTM!$C:$C,0)),"@")="—")),EXACT(TEXT(D4,"@"),TEXT(INDEX(KhoiVTM!$J:$J,MATCH(B4,KhoiVTM!$C:$C,0)),"@"))),FALSE())*1)+(IFERROR(OR(AND(OR(E4="—",E4=""),OR(TEXT(INDEX(KhoiVTM!$M:$M,MATCH(B4,KhoiVTM!$C:$C,0)),"@")="",TEXT(INDEX(KhoiVTM!$M:$M,MATCH(B4,KhoiVTM!$C:$C,0)),"@")="—")),EXACT(TEXT(E4,"@"),TEXT(INDEX(KhoiVTM!$M:$M,MATCH(B4,KhoiVTM!$C:$C,0)),"@"))),FALSE())*1)>=3,"Partial","Mismatch"))),"Not Found") -> Partial
A5: =KhoiVTM!A5 -> 4 | B5: =KhoiVTM!C5 -> AD8130ARMZ-REEL | C5: =KhoiVTM!D5 -> IC OPAMP DIFF 1 CIRCUIT 8MSOP | D5: — | E5: 8-TSSOP | F5: =KhoiVTM!F5 -> 6 | G5: 4 | H5: 0 | I5: =F5-H5 -> 6 | J5: =IF(LEFT(C5,3)="RES", "Resistor", IF(LEFT(C5,3)="CAP", "Capacitor", "Other")) -> Other | K5: Ordering | N5: =IFERROR(IF(ISERROR(MATCH(B5,KhoiVTM!$C:$C,0)),"Not Found",IF((EXACT(C5,IFERROR(INDEX(KhoiVTM!$D:$D,MATCH(B5,KhoiVTM!$C:$C,0)),"__NA__"))*1)+(IFERROR(F5=INDEX(KhoiVTM!$F:$F,MATCH(B5,KhoiVTM!$C:$C,0)),FALSE())*1)+(IFERROR(OR(AND(OR(D5="—",D5=""),OR(TEXT(INDEX(KhoiVTM!$J:$J,MATCH(B5,KhoiVTM!$C:$C,0)),"@")="",TEXT(INDEX(KhoiVTM!$J:$J,MATCH(B5,KhoiVTM!$C:$C,0)),"@")="—")),EXACT(TEXT(D5,"@"),TEXT(INDEX(KhoiVTM!$J:$J,MATCH(B5,KhoiVTM!$C:$C,0)),"@"))),FALSE())*1)+(IFERROR(OR(AND(OR(E5="—",E5=""),OR(TEXT(INDEX(KhoiVTM!$M:$M,MATCH(B5,KhoiVTM!$C:$C,0)),"@")="",TEXT(INDEX(KhoiVTM!$M:$M,MATCH(B5,KhoiVTM!$C:$C,0)),"@")="—")),EXACT(TEXT(E5,"@"),TEXT(INDEX(KhoiVTM!$M:$M,MATCH(B5,KhoiVTM!$C:$C,0)),"@"))),FALSE())*1)=4,"Match",IF((EXACT(C5,IFERROR(INDEX(KhoiVTM!$D:$D,MATCH(B5,KhoiVTM!$C:$C,0)),"__NA__"))*1)+(IFERROR(F5=INDEX(KhoiVTM!$F:$F,MATCH(B5,KhoiVTM!$C:$C,0)),FALSE())*1)+(IFERROR(OR(AND(OR(D5="—",D5=""),OR(TEXT(INDEX(KhoiVTM!$J:$J,MATCH(B5,KhoiVTM!$C:$C,0)),"@")="",TEXT(INDEX(KhoiVTM!$J:$J,MATCH(B5,KhoiVTM!$C:$C,0)),"@")="—")),EXACT(TEXT(D5,"@"),TEXT(INDEX(KhoiVTM!$J:$J,MATCH(B5,KhoiVTM!$C:$C,0)),"@"))),FALSE())*1)+(IFERROR(OR(AND(OR(E5="—",E5=""),OR(TEXT(INDEX(KhoiVTM!$M:$M,MATCH(B5,KhoiVTM!$C:$C,0)),"@")="",TEXT(INDEX(KhoiVTM!$M:$M,MATCH(B5,KhoiVTM!$C:$C,0)),"@")="—")),EXACT(TEXT(E5,"@"),TEXT(INDEX(KhoiVTM!$M:$M,MATCH(B5,KhoiVTM!$C:$C,0)),"@"))),FALSE())*1)>=3,"Partial","Mismatch"))),"Not Found") -> Partial
A6: =KhoiVTM!A6 -> 5 | B6: =KhoiVTM!C6 -> TNPW06036K80BEEA | C6: =KhoiVTM!D6 -> RES 6.8K OHM 0.1% 0.21W 0603 | D6: 6.8K | E6: =RIGHT(TRIM(C6), 4) -> 0603 | F6: =KhoiVTM!F6 -> 25 | G6: =Kicad_Extract!D35 -> 1 | H6: 0 | I6: =F6-H6 -> 25 | J6: =IF(LEFT(C6,3)="RES", "Resistor", IF(LEFT(C6,3)="CAP", "Capacitor", "Other")) -> Resistor | K6: Done | N6: =IFERROR(IF(ISERROR(MATCH(B6,KhoiVTM!$C:$C,0)),"Not Found",IF((EXACT(C6,IFERROR(INDEX(KhoiVTM!$D:$D,MATCH(B6,KhoiVTM!$C:$C,0)),"__NA__"))*1)+(IFERROR(F6=INDEX(KhoiVTM!$F:$F,MATCH(B6,KhoiVTM!$C:$C,0)),FALSE())*1)+(IFERROR(OR(AND(OR(D6="—",D6=""),OR(TEXT(INDEX(KhoiVTM!$J:$J,MATCH(B6,KhoiVTM!$C:$C,0)),"@")="",TEXT(INDEX(KhoiVTM!$J:$J,MATCH(B6,KhoiVTM!$C:$C,0)),"@")="—")),EXACT(TEXT(D6,"@"),TEXT(INDEX(KhoiVTM!$J:$J,MATCH(B6,KhoiVTM!$C:$C,0)),"@"))),FALSE())*1)+(IFERROR(OR(AND(OR(E6="—",E6=""),OR(TEXT(INDEX(KhoiVTM!$M:$M,MATCH(B6,KhoiVTM!$C:$C,0)),"@")="",TEXT(INDEX(KhoiVTM!$M:$M,MATCH(B6,KhoiVTM!$C:$C,0)),"@")="—")),EXACT(TEXT(E6,"@"),TEXT(INDEX(KhoiVTM!$M:$M,MATCH(B6,KhoiVTM!$C:$C,0)),"@"))),FALSE())*1)=4,"Match",IF((EXACT(C6,IFERROR(INDEX(KhoiVTM!$D:$D,MATCH(B6,KhoiVTM!$C:$C,0)),"__NA__"))*1)+(IFERROR(F6=INDEX(KhoiVTM!$F:$F,MATCH(B6,KhoiVTM!$C:$C,0)),FALSE())*1)+(IFERROR(OR(AND(OR(D6="—",D6=""),OR(TEXT(INDEX(KhoiVTM!$J:$J,MATCH(B6,KhoiVTM!$C:$C,0)),"@")="",TEXT(INDEX(KhoiVTM!$J:$J,MATCH(B6,KhoiVTM!$C:$C,0)),"@")="—")),EXACT(TEXT(D6,"@"),TEXT(INDEX(KhoiVTM!$J:$J,MATCH(B6,KhoiVTM!$C:$C,0)),"@"))),FALSE())*1)+(IFERROR(OR(AND(OR(E6="—",E6=""),OR(TEXT(INDEX(KhoiVTM!$M:$M,MATCH(B6,KhoiVTM!$C:$C,0)),"@")="",TEXT(INDEX(KhoiVTM!$M:$M,MATCH(B6,KhoiVTM!$C:$C,0)),"@")="—")),EXACT(TEXT(E6,"@"),TEXT(INDEX(KhoiVTM!$M:$M,MATCH(B6,KhoiVTM!$C:$C,0)),"@"))),FALSE())*1)>=3,"Partial","Mismatch"))),"Not Found") -> Match
A7: =KhoiVTM!A7 -> 6 | B7: =KhoiVTM!C7 -> TNPW0603200RBEEA | C7: =KhoiVTM!D7 -> RES 200 OHM 0.1% 0.21W 0603 | D7: 200 | E7: =RIGHT(TRIM(C7), 4) -> 0603 | F7: =KhoiVTM!F7 -> 25 | G7: 2 | H7: 0 | I7: =F7-H7 -> 25 | J7: =IF(LEFT(C7,3)="RES", "Resistor", IF(LEFT(C7,3)="CAP", "Capacitor", "Other")) -> Resistor | K7: Done | N7: =IFERROR(IF(ISERROR(MATCH(B7,KhoiVTM!$C:$C,0)),"Not Found",IF((EXACT(C7,IFERROR(INDEX(KhoiVTM!$D:$D,MATCH(B7,KhoiVTM!$C:$C,0)),"__NA__"))*1)+(IFERROR(F7=INDEX(KhoiVTM!$F:$F,MATCH(B7,KhoiVTM!$C:$C,0)),FALSE())*1)+(IFERROR(OR(AND(OR(D7="—",D7=""),OR(TEXT(INDEX(KhoiVTM!$J:$J,MATCH(B7,KhoiVTM!$C:$C,0)),"@")="",TEXT(INDEX(KhoiVTM!$J:$J,MATCH(B7,KhoiVTM!$C:$C,0)),"@")="—")),EXACT(TEXT(D7,"@"),TEXT(INDEX(KhoiVTM!$J:$J,MATCH(B7,KhoiVTM!$C:$C,0)),"@"))),FALSE())*1)+(IFERROR(OR(AND(OR(E7="—",E7=""),OR(TEXT(INDEX(KhoiVTM!$M:$M,MATCH(B7,KhoiVTM!$C:$C,0)),"@")="",TEXT(INDEX(KhoiVTM!$M:$M,MATCH(B7,KhoiVTM!$C:$C,0)),"@")="—")),EXACT(TEXT(E7,"@"),TEXT(INDEX(KhoiVTM!$M:$M,MATCH(B7,KhoiVTM!$C:$C,0)),"@"))),FALSE())*1)=4,"Match",IF((EXACT(C7,IFERROR(INDEX(KhoiVTM!$D:$D,MATCH(B7,KhoiVTM!$C:$C,0)),"__NA__"))*1)+(IFERROR(F7=INDEX(KhoiVTM!$F:$F,MATCH(B7,KhoiVTM!$C:$C,0)),FALSE())*1)+(IFERROR(OR(AND(OR(D7="—",D7=""),OR(TEXT(INDEX(KhoiVTM!$J:$J,MATCH(B7,KhoiVTM!$C:$C,0)),"@")="",TEXT(INDEX(KhoiVTM!$J:$J,MATCH(B7,KhoiVTM!$C:$C,0)),"@")="—")),EXACT(TEXT(D7,"@"),TEXT(INDEX(KhoiVTM!$J:$J,MATCH(B7,KhoiVTM!$C:$C,0)),"@"))),FALSE())*1)+(IFERROR(OR(AND(OR(E7="—",E7=""),OR(TEXT(INDEX(KhoiVTM!$M:$M,MATCH(B7,KhoiVTM!$C:$C,0)),"@")="",TEXT(INDEX(KhoiVTM!$M:$M,MATCH(B7,KhoiVTM!$C:$C,0)),"@")="—")),EXACT(TEXT(E7,"@"),TEXT(INDEX(KhoiVTM!$M:$M,MATCH(B7,KhoiVTM!$C:$C,0)),"@"))),FALSE())*1)>=3,"Partial","Mismatch"))),"Not Found") -> Match
A8: =KhoiVTM!A8 -> 7 | B8: =KhoiVTM!C8 -> TNPW0603280RBEEA | C8: =KhoiVTM!D8 -> RES 280 OHM 0.1% 0.21W 0603 | D8: 280 | E8: =RIGHT(TRIM(C8), 4) -> 0603 | F8: =KhoiVTM!F8 -> 25 | G8: 0 | H8: 0 | I8: =F8-H8 -> 25 | J8: =IF(LEFT(C8,3)="RES", "Resistor", IF(LEFT(C8,3)="CAP", "Capacitor", "Other")) -> Resistor | K8: Done | N8: =IFERROR(IF(ISERROR(MATCH(B8,KhoiVTM!$C:$C,0)),"Not Found",IF((EXACT(C8,IFERROR(INDEX(KhoiVTM!$D:$D,MATCH(B8,KhoiVTM!$C:$C,0)),"__NA__"))*1)+(IFERROR(F8=INDEX(KhoiVTM!$F:$F,MATCH(B8,KhoiVTM!$C:$C,0)),FALSE())*1)+(IFERROR(OR(AND(OR(D8="—",D8=""),OR(TEXT(INDEX(KhoiVTM!$J:$J,MATCH(B8,KhoiVTM!$C:$C,0)),"@")="",TEXT(INDEX(KhoiVTM!$J:$J,MATCH(B8,KhoiVTM!$C:$C,0)),"@")="—")),EXACT(TEXT(D8,"@"),TEXT(INDEX(KhoiVTM!$J:$J,MATCH(B8,KhoiVTM!$C:$C,0)),"@"))),FALSE())*1)+(IFERROR(OR(AND(OR(E8="—",E8=""),OR(TEXT(INDEX(KhoiVTM!$M:$M,MATCH(B8,KhoiVTM!$C:$C,0)),"@")="",TEXT(INDEX(KhoiVTM!$M:$M,MATCH(B8,KhoiVTM!$C:$C,0)),"@")="—")),EXACT(TEXT(E8,"@"),TEXT(INDEX(KhoiVTM!$M:$M,MATCH(B8,KhoiVTM!$C:$C,0)),"@"))),FALSE())*1)=4,"Match",IF((EXACT(C8,IFERROR(INDEX(KhoiVTM!$D:$D,MATCH(B8,KhoiVTM!$C:$C,0)),"__NA__"))*1)+(IFERROR(F8=INDEX(KhoiVTM!$F:$F,MATCH(B8,KhoiVTM!$C:$C,0)),FALSE())*1)+(IFERROR(OR(AND(OR(D8="—",D8=""),OR(TEXT(INDEX(KhoiVTM!$J:$J,MATCH(B8,KhoiVTM!$C:$C,0)),"@")="",TEXT(INDEX(KhoiVTM!$J:$J,MATCH(B8,KhoiVTM!$C:$C,0)),"@")="—")),EXACT(TEXT(D8,"@"),TEXT(INDEX(KhoiVTM!$J:$J,MATCH(B8,KhoiVTM!$C:$C,0)),"@"))),FALSE())*1)+(IFERROR(OR(AND(OR(E8="—",E8=""),OR(TEXT(INDEX(KhoiVTM!$M:$M,MATCH(B8,KhoiVTM!$C:$C,0)),"@")="",TEXT(INDEX(KhoiVTM!$M:$M,MATCH(B8,KhoiVTM!$C:$C,0)),"@")="—")),EXACT(TEXT(E8,"@"),TEXT(INDEX(KhoiVTM!$M:$M,MATCH(B8,KhoiVTM!$C:$C,0)),"@"))),FALSE())*1)>=3,"Partial","Mismatch"))),"Not Found") -> Match
A9: =KhoiVTM!A9 -> 8 | B9: =KhoiVTM!C9 -> TNP1.00KAATR-ND | C9: =KhoiVTM!D9 -> RES 1K OHM 0.1% 0.21W 0603 | D9: 1K | E9: =RIGHT(TRIM(C9), 4) -> 0603 | F9: =KhoiVTM!F9 -> 25 | G9: 2 | H9: 0 | I9: =F9-H9 -> 25 | J9: =IF(LEFT(C9,3)="RES", "Resistor", IF(LEFT(C9,3)="CAP", "Capacitor", "Other")) -> Resistor | K9: Done | N9: =IFERROR(IF(ISERROR(MATCH(B9,KhoiVTM!$C:$C,0)),"Not Found",IF((EXACT(C9,IFERROR(INDEX(KhoiVTM!$D:$D,MATCH(B9,KhoiVTM!$C:$C,0)),"__NA__"))*1)+(IFERROR(F9=INDEX(KhoiVTM!$F:$F,MATCH(B9,KhoiVTM!$C:$C,0)),FALSE())*1)+(IFERROR(OR(AND(OR(D9="—",D9=""),OR(TEXT(INDEX(KhoiVTM!$J:$J,MATCH(B9,KhoiVTM!$C:$C,0)),"@")="",TEXT(INDEX(KhoiVTM!$J:$J,MATCH(B9,KhoiVTM!$C:$C,0)),"@")="—")),EXACT(TEXT(D9,"@"),TEXT(INDEX(KhoiVTM!$J:$J,MATCH(B9,KhoiVTM!$C:$C,0)),"@"))),FALSE())*1)+(IFERROR(OR(AND(OR(E9="—",E9=""),OR(TEXT(INDEX(KhoiVTM!$M:$M,MATCH(B9,KhoiVTM!$C:$C,0)),"@")="",TEXT(INDEX(KhoiVTM!$M:$M,MATCH(B9,KhoiVTM!$C:$C,0)),"@")="—")),EXACT(TEXT(E9,"@"),TEXT(INDEX(KhoiVTM!$M:$M,MATCH(B9,KhoiVTM!$C:$C,0)),"@"))),FALSE())*1)=4,"Match",IF((EXACT(C9,IFERROR(INDEX(KhoiVTM!$D:$D,MATCH(B9,KhoiVTM!$C:$C,0)),"__NA__"))*1)+(IFERROR(F9=INDEX(KhoiVTM!$F:$F,MATCH(B9,KhoiVTM!$C:$C,0)),FALSE())*1)+(IFERROR(OR(AND(OR(D9="—",D9=""),OR(TEXT(INDEX(KhoiVTM!$J:$J,MATCH(B9,KhoiVTM!$C:$C,0)),"@")="",TEXT(INDEX(KhoiVTM!$J:$J,MATCH(B9,KhoiVTM!$C:$C,0)),"@")="—")),EXACT(TEXT(D9,"@"),TEXT(INDEX(KhoiVTM!$J:$J,MATCH(B9,KhoiVTM!$C:$C,0)),"@"))),FALSE())*1)+(IFERROR(OR(AND(OR(E9="—",E9=""),OR(TEXT(INDEX(KhoiVTM!$M:$M,MATCH(B9,KhoiVTM!$C:$C,0)),"@")="",TEXT(INDEX(KhoiVTM!$M:$M,MATCH(B9,KhoiVTM!$C:$C,0)),"@")="—")),EXACT(TEXT(E9,"@"),TEXT(INDEX(KhoiVTM!$M:$M,MATCH(B9,KhoiVTM!$C:$C,0)),"@"))),FALSE())*1)>=3,"Partial","Mismatch"))),"Not Found") -> Match
A10: =KhoiVTM!A10 -> 9 | B10: =KhoiVTM!C10 -> RC0603FR-0722RL | C10: =KhoiVTM!D10 -> RES 22 OHM 1% 1/10W 0603 | D10: 22 | E10: =RIGHT(TRIM(C10), 4) -> 0603 | F10: =KhoiVTM!F10 -> 25 | G10: 3 | H10: 0 | I10: =F10-H10 -> 25 | J10: =IF(LEFT(C10,3)="RES", "Resistor", IF(LEFT(C10,3)="CAP", "Capacitor", "Other")) -> Resistor | K10: Done | N10: =IFERROR(IF(ISERROR(MATCH(B10,KhoiVTM!$C:$C,0)),"Not Found",IF((EXACT(C10,IFERROR(INDEX(KhoiVTM!$D:$D,MATCH(B10,KhoiVTM!$C:$C,0)),"__NA__"))*1)+(IFERROR(F10=INDEX(KhoiVTM!$F:$F,MATCH(B10,KhoiVTM!$C:$C,0)),FALSE())*1)+(IFERROR(OR(AND(OR(D10="—",D10=""),OR(TEXT(INDEX(KhoiVTM!$J:$J,MATCH(B10,KhoiVTM!$C:$C,0)),"@")="",TEXT(INDEX(KhoiVTM!$J:$J,MATCH(B10,KhoiVTM!$C:$C,0)),"@")="—")),EXACT(TEXT(D10,"@"),TEXT(INDEX(KhoiVTM!$J:$J,MATCH(B10,KhoiVTM!$C:$C,0)),"@"))),FALSE())*1)+(IFERROR(OR(AND(OR(E10="—",E10=""),OR(TEXT(INDEX(KhoiVTM!$M:$M,MATCH(B10,KhoiVTM!$C:$C,0)),"@")="",TEXT(INDEX(KhoiVTM!$M:$M,MATCH(B10,KhoiVTM!$C:$C,0)),"@")="—")),EXACT(TEXT(E10,"@"),TEXT(INDEX(KhoiVTM!$M:$M,MATCH(B10,KhoiVTM!$C:$C,0)),"@"))),FALSE())*1)=4,"Match",IF((EXACT(C10,IFERROR(INDEX(KhoiVTM!$D:$D,MATCH(B10,KhoiVTM!$C:$C,0)),"__NA__"))*1)+(IFERROR(F10=INDEX(KhoiVTM!$F:$F,MATCH(B10,KhoiVTM!$C:$C,0)),FALSE())*1)+(IFERROR(OR(AND(OR(D10="—",D10=""),OR(TEXT(INDEX(KhoiVTM!$J:$J,MATCH(B10,KhoiVTM!$C:$C,0)),"@")="",TEXT(INDEX(KhoiVTM!$J:$J,MATCH(B10,KhoiVTM!$C:$C,0)),"@")="—")),EXACT(TEXT(D10,"@"),TEXT(INDEX(KhoiVTM!$J:$J,MATCH(B10,KhoiVTM!$C:$C,0)),"@"))),FALSE())*1)+(IFERROR(OR(AND(OR(E10="—",E10=""),OR(TEXT(INDEX(KhoiVTM!$M:$M,MATCH(B10,KhoiVTM!$C:$C,0)),"@")="",TEXT(INDEX(KhoiVTM!$M:$M,MATCH(B10,KhoiVTM!$C:$C,0)),"@")="—")),EXACT(TEXT(E10,"@"),TEXT(INDEX(KhoiVTM!$M:$M,MATCH(B10,KhoiVTM!$C:$C,0)),"@"))),FALSE())*1)>=3,"Partial","Mismatch"))),"Not Found") -> Match
A11: =KhoiVTM!A11 -> 10 | B11: =KhoiVTM!C11 -> RC0603JR-070RL | C11: =KhoiVTM!D11 -> RES 0 OHM JUMPER 1/10W 0603 | D11: 0 | E11: =RIGHT(TRIM(C11), 4) -> 0603 | F11: =KhoiVTM!F11 -> 25 | G11: 6 | H11: 0 | I11: =F11-H11 -> 25 | J11: =IF(LEFT(C11,3)="RES", "Resistor", IF(LEFT(C11,3)="CAP", "Capacitor", "Other")) -> Resistor | K11: Done | N11: =IFERROR(IF(ISERROR(MATCH(B11,KhoiVTM!$C:$C,0)),"Not Found",IF((EXACT(C11,IFERROR(INDEX(KhoiVTM!$D:$D,MATCH(B11,KhoiVTM!$C:$C,0)),"__NA__"))*1)+(IFERROR(F11=INDEX(KhoiVTM!$F:$F,MATCH(B11,KhoiVTM!$C:$C,0)),FALSE())*1)+(IFERROR(OR(AND(OR(D11="—",D11=""),OR(TEXT(INDEX(KhoiVTM!$J:$J,MATCH(B11,KhoiVTM!$C:$C,0)),"@")="",TEXT(INDEX(KhoiVTM!$J:$J,MATCH(B11,KhoiVTM!$C:$C,0)),"@")="—")),EXACT(TEXT(D11,"@"),TEXT(INDEX(KhoiVTM!$J:$J,MATCH(B11,KhoiVTM!$C:$C,0)),"@"))),FALSE())*1)+(IFERROR(OR(AND(OR(E11="—",E11=""),OR(TEXT(INDEX(KhoiVTM!$M:$M,MATCH(B11,KhoiVTM!$C:$C,0)),"@")="",TEXT(INDEX(KhoiVTM!$M:$M,MATCH(B11,KhoiVTM!$C:$C,0)),"@")="—")),EXACT(TEXT(E11,"@"),TEXT(INDEX(KhoiVTM!$M:$M,MATCH(B11,KhoiVTM!$C:$C,0)),"@"))),FALSE())*1)=4,"Match",IF((EXACT(C11,IFERROR(INDEX(KhoiVTM!$D:$D,MATCH(B11,KhoiVTM!$C:$C,0)),"__NA__"))*1)+(IFERROR(F11=INDEX(KhoiVTM!$F:$F,MATCH(B11,KhoiVTM!$C:$C,0)),FALSE())*1)+(IFERROR(OR(AND(OR(D11="—",D11=""),OR(TEXT(INDEX(KhoiVTM!$J:$J,MATCH(B11,KhoiVTM!$C:$C,0)),"@")="",TEXT(INDEX(KhoiVTM!$J:$J,MATCH(B11,KhoiVTM!$C:$C,0)),"@")="—")),EXACT(TEXT(D11,"@"),TEXT(INDEX(KhoiVTM!$J:$J,MATCH(B11,KhoiVTM!$C:$C,0)),"@"))),FALSE())*1)+(IFERROR(OR(AND(OR(E11="—",E11=""),OR(TEXT(INDEX(KhoiVTM!$M:$M,MATCH(B11,KhoiVTM!$C:$C,0)),"@")="",TEXT(INDEX(KhoiVTM!$M:$M,MATCH(B11,KhoiVTM!$C:$C,0)),"@")="—")),EXACT(TEXT(E11,"@"),TEXT(INDEX(KhoiVTM!$M:$M,MATCH(B11,KhoiVTM!$C:$C,0)),"@"))),FALSE())*1)>=3,"Partial","Mismatch"))),"Not Found") -> Match
A12: =KhoiVTM!A12 -> 11 | B12: =KhoiVTM!C12 -> TNPW0603499RBEEA | C12: =KhoiVTM!D12 -> RES 499 OHM 0.1% 0.21W 0603 | D12: 499 | E12: =RIGHT(TRIM(C12), 4) -> 0603 | F12: =KhoiVTM!F12 -> 25 | G12: 6 | H12: 0 | I12: =F12-H12 -> 25 | J12: =IF(LEFT(C12,3)="RES", "Resistor", IF(LEFT(C12,3)="CAP", "Capacitor", "Other")) -> Resistor | K12: Done | N12: =IFERROR(IF(ISERROR(MATCH(B12,KhoiVTM!$C:$C,0)),"Not Found",IF((EXACT(C12,IFERROR(INDEX(KhoiVTM!$D:$D,MATCH(B12,KhoiVTM!$C:$C,0)),"__NA__"))*1)+(IFERROR(F12=INDEX(KhoiVTM!$F:$F,MATCH(B12,KhoiVTM!$C:$C,0)),FALSE())*1)+(IFERROR(OR(AND(OR(D12="—",D12=""),OR(TEXT(INDEX(KhoiVTM!$J:$J,MATCH(B12,KhoiVTM!$C:$C,0)),"@")="",TEXT(INDEX(KhoiVTM!$J:$J,MATCH(B12,KhoiVTM!$C:$C,0)),"@")="—")),EXACT(TEXT(D12,"@"),TEXT(INDEX(KhoiVTM!$J:$J,MATCH(B12,KhoiVTM!$C:$C,0)),"@"))),FALSE())*1)+(IFERROR(OR(AND(OR(E12="—",E12=""),OR(TEXT(INDEX(KhoiVTM!$M:$M,MATCH(B12,KhoiVTM!$C:$C,0)),"@")="",TEXT(INDEX(KhoiVTM!$M:$M,MATCH(B12,KhoiVTM!$C:$C,0)),"@")="—")),EXACT(TEXT(E12,"@"),TEXT(INDEX(KhoiVTM!$M:$M,MATCH(B12,KhoiVTM!$C:$C,0)),"@"))),FALSE())*1)=4,"Match",IF((EXACT(C12,IFERROR(INDEX(KhoiVTM!$D:$D,MATCH(B12,KhoiVTM!$C:$C,0)),"__NA__"))*1)+(IFERROR(F12=INDEX(KhoiVTM!$F:$F,MATCH(B12,KhoiVTM!$C:$C,0)),FALSE())*1)+(IFERROR(OR(AND(OR(D12="—",D12=""),OR(TEXT(INDEX(KhoiVTM!$J:$J,MATCH(B12,KhoiVTM!$C:$C,0)),"@")="",TEXT(INDEX(KhoiVTM!$J:$J,MATCH(B12,KhoiVTM!$C:$C,0)),"@")="—")),EXACT(TEXT(D12,"@"),TEXT(INDEX(KhoiVTM!$J:$J,MATCH(B12,KhoiVTM!$C:$C,0)),"@"))),FALSE())*1)+(IFERROR(OR(AND(OR(E12="—",E12=""),OR(TEXT(INDEX(KhoiVTM!$M:$M,MATCH(B12,KhoiVTM!$C:$C,0)),"@")="",TEXT(INDEX(KhoiVTM!$M:$M,MATCH(B12,KhoiVTM!$C:$C,0)),"@")="—")),EXACT(TEXT(E12,"@"),TEXT(INDEX(KhoiVTM!$M:$M,MATCH(B12,KhoiVTM!$C:$C,0)),"@"))),FALSE())*1)>=3,"Partial","Mismatch"))),"Not Found") -> Match
A13: =KhoiVTM!A13 -> 12 | B13: =KhoiVTM!C13 -> 541-TNPW06031K78BEEATR-ND | C13: =KhoiVTM!D13 -> RES 1.78K OHM 0.1% 0.21W 0603 | D13: 1.78K | E13: =RIGHT(TRIM(C13), 4) -> 0603 | F13: =KhoiVTM!F13 -> 25 | G13: 0 | H13: 0 | I13: =F13-H13 -> 25 | J13: =IF(LEFT(C13,3)="RES", "Resistor", IF(LEFT(C13,3)="CAP", "Capacitor", "Other")) -> Resistor | K13: Done | N13: =IFERROR(IF(ISERROR(MATCH(B13,KhoiVTM!$C:$C,0)),"Not Found",IF((EXACT(C13,IFERROR(INDEX(KhoiVTM!$D:$D,MATCH(B13,KhoiVTM!$C:$C,0)),"__NA__"))*1)+(IFERROR(F13=INDEX(KhoiVTM!$F:$F,MATCH(B13,KhoiVTM!$C:$C,0)),FALSE())*1)+(IFERROR(OR(AND(OR(D13="—",D13=""),OR(TEXT(INDEX(KhoiVTM!$J:$J,MATCH(B13,KhoiVTM!$C:$C,0)),"@")="",TEXT(INDEX(KhoiVTM!$J:$J,MATCH(B13,KhoiVTM!$C:$C,0)),"@")="—")),EXACT(TEXT(D13,"@"),TEXT(INDEX(KhoiVTM!$J:$J,MATCH(B13,KhoiVTM!$C:$C,0)),"@"))),FALSE())*1)+(IFERROR(OR(AND(OR(E13="—",E13=""),OR(TEXT(INDEX(KhoiVTM!$M:$M,MATCH(B13,KhoiVTM!$C:$C,0)),"@")="",TEXT(INDEX(KhoiVTM!$M:$M,MATCH(B13,KhoiVTM!$C:$C,0)),"@")="—")),EXACT(TEXT(E13,"@"),TEXT(INDEX(KhoiVTM!$M:$M,MATCH(B13,KhoiVTM!$C:$C,0)),"@"))),FALSE())*1)=4,"Match",IF((EXACT(C13,IFERROR(INDEX(KhoiVTM!$D:$D,MATCH(B13,KhoiVTM!$C:$C,0)),"__NA__"))*1)+(IFERROR(F13=INDEX(KhoiVTM!$F:$F,MATCH(B13,KhoiVTM!$C:$C,0)),FALSE())*1)+(IFERROR(OR(AND(OR(D13="—",D13=""),OR(TEXT(INDEX(KhoiVTM!$J:$J,MATCH(B13,KhoiVTM!$C:$C,0)),"@")="",TEXT(INDEX(KhoiVTM!$J:$J,MATCH(B13,KhoiVTM!$C:$C,0)),"@")="—")),EXACT(TEXT(D13,"@"),TEXT(INDEX(KhoiVTM!$J:$J,MATCH(B13,KhoiVTM!$C:$C,0)),"@"))),FALSE())*1)+(IFERROR(OR(AND(OR(E13="—",E13=""),OR(TEXT(INDEX(KhoiVTM!$M:$M,MATCH(B13,KhoiVTM!$C:$C,0)),"@")="",TEXT(INDEX(KhoiVTM!$M:$M,MATCH(B13,KhoiVTM!$C:$C,0)),"@")="—")),EXACT(TEXT(E13,"@"),TEXT(INDEX(KhoiVTM!$M:$M,MATCH(B13,KhoiVTM!$C:$C,0)),"@"))),FALSE())*1)>=3,"Partial","Mismatch"))),"Not Found") -> Match
A14: =KhoiVTM!A14 -> 13 | B14: =KhoiVTM!C14 -> RC0603FR-07510RL | C14: =KhoiVTM!D14 -> RES 510 OHM 1% 1/10W 0603 | D14: 510 | E14: =RIGHT(TRIM(C14), 4) -> 0603 | F14: =KhoiVTM!F14 -> 25 | G14: 0 | H14: 0 | I14: =F14-H14 -> 25 | J14: =IF(LEFT(C14,3)="RES", "Resistor", IF(LEFT(C14,3)="CAP", "Capacitor", "Other")) -> Resistor | K14: Done | N14: =IFERROR(IF(ISERROR(MATCH(B14,KhoiVTM!$C:$C,0)),"Not Found",IF((EXACT(C14,IFERROR(INDEX(KhoiVTM!$D:$D,MATCH(B14,KhoiVTM!$C:$C,0)),"__NA__"))*1)+(IFERROR(F14=INDEX(KhoiVTM!$F:$F,MATCH(B14,KhoiVTM!$C:$C,0)),FALSE())*1)+(IFERROR(OR(AND(OR(D14="—",D14=""),OR(TEXT(INDEX(KhoiVTM!$J:$J,MATCH(B14,KhoiVTM!$C:$C,0)),"@")="",TEXT(INDEX(KhoiVTM!$J:$J,MATCH(B14,KhoiVTM!$C:$C,0)),"@")="—")),EXACT(TEXT(D14,"@"),TEXT(INDEX(KhoiVTM!$J:$J,MATCH(B14,KhoiVTM!$C:$C,0)),"@"))),FALSE())*1)+(IFERROR(OR(AND(OR(E14="—",E14=""),OR(TEXT(INDEX(KhoiVTM!$M:$M,MATCH(B14,KhoiVTM!$C:$C,0)),"@")="",TEXT(INDEX(KhoiVTM!$M:$M,MATCH(B14,KhoiVTM!$C:$C,0)),"@")="—")),EXACT(TEXT(E14,"@"),TEXT(INDEX(KhoiVTM!$M:$M,MATCH(B14,KhoiVTM!$C:$C,0)),"@"))),FALSE())*1)=4,"Match",IF((EXACT(C14,IFERROR(INDEX(KhoiVTM!$D:$D,MATCH(B14,KhoiVTM!$C:$C,0)),"__NA__"))*1)+(IFERROR(F14=INDEX(KhoiVTM!$F:$F,MATCH(B14,KhoiVTM!$C:$C,0)),FALSE())*1)+(IFERROR(OR(AND(OR(D14="—",D14=""),OR(TEXT(INDEX(KhoiVTM!$J:$J,MATCH(B14,KhoiVTM!$C:$C,0)),"@")="",TEXT(INDEX(KhoiVTM!$J:$J,MATCH(B14,KhoiVTM!$C:$C,0)),"@")="—")),EXACT(TEXT(D14,"@"),TEXT(INDEX(KhoiVTM!$J:$J,MATCH(B14,KhoiVTM!$C:$C,0)),"@"))),FALSE())*1)+(IFERROR(OR(AND(OR(E14="—",E14=""),OR(TEXT(INDEX(KhoiVTM!$M:$M,MATCH(B14,KhoiVTM!$C:$C,0)),"@")="",TEXT(INDEX(KhoiVTM!$M:$M,MATCH(B14,KhoiVTM!$C:$C,0)),"@")="—")),EXACT(TEXT(E14,"@"),TEXT(INDEX(KhoiVTM!$M:$M,MATCH(B14,KhoiVTM!$C:$C,0)),"@"))),FALSE())*1)>=3,"Partial","Mismatch"))),"Not Found") -> Match
A15: =KhoiVTM!A15 -> 14 | B15: =KhoiVTM!C15 -> RC0603FR-072K67L | C15: =KhoiVTM!D15 -> RES 2.67K OHM 1% 0.1W, 1/10W 0603 | D15: 2.67K | E15: =RIGHT(TRIM(C15), 4) -> 0603 | F15: =KhoiVTM!F15 -> 25 | G15: 0 | H15: 0 | I15: =F15-H15 -> 25 | J15: =IF(LEFT(C15,3)="RES", "Resistor", IF(LEFT(C15,3)="CAP", "Capacitor", "Other")) -> Resistor | K15: Done | N15: =IFERROR(IF(ISERROR(MATCH(B15,KhoiVTM!$C:$C,0)),"Not Found",IF((EXACT(C15,IFERROR(INDEX(KhoiVTM!$D:$D,MATCH(B15,KhoiVTM!$C:$C,0)),"__NA__"))*1)+(IFERROR(F15=INDEX(KhoiVTM!$F:$F,MATCH(B15,KhoiVTM!$C:$C,0)),FALSE())*1)+(IFERROR(OR(AND(OR(D15="—",D15=""),OR(TEXT(INDEX(KhoiVTM!$J:$J,MATCH(B15,KhoiVTM!$C:$C,0)),"@")="",TEXT(INDEX(KhoiVTM!$J:$J,MATCH(B15,KhoiVTM!$C:$C,0)),"@")="—")),EXACT(TEXT(D15,"@"),TEXT(INDEX(KhoiVTM!$J:$J,MATCH(B15,KhoiVTM!$C:$C,0)),"@"))),FALSE())*1)+(IFERROR(OR(AND(OR(E15="—",E15=""),OR(TEXT(INDEX(KhoiVTM!$M:$M,MATCH(B15,KhoiVTM!$C:$C,0)),"@")="",TEXT(INDEX(KhoiVTM!$M:$M,MATCH(B15,KhoiVTM!$C:$C,0)),"@")="—")),EXACT(TEXT(E15,"@"),TEXT(INDEX(KhoiVTM!$M:$M,MATCH(B15,KhoiVTM!$C:$C,0)),"@"))),FALSE())*1)=4,"Match",IF((EXACT(C15,IFERROR(INDEX(KhoiVTM!$D:$D,MATCH(B15,KhoiVTM!$C:$C,0)),"__NA__"))*1)+(IFERROR(F15=INDEX(KhoiVTM!$F:$F,MATCH(B15,KhoiVTM!$C:$C,0)),FALSE())*1)+(IFERROR(OR(AND(OR(D15="—",D15=""),OR(TEXT(INDEX(KhoiVTM!$J:$J,MATCH(B15,KhoiVTM!$C:$C,0)),"@")="",TEXT(INDEX(KhoiVTM!$J:$J,MATCH(B15,KhoiVTM!$C:$C,0)),"@")="—")),EXACT(TEXT(D15,"@"),TEXT(INDEX(KhoiVTM!$J:$J,MATCH(B15,KhoiVTM!$C:$C,0)),"@"))),FALSE())*1)+(IFERROR(OR(AND(OR(E15="—",E15=""),OR(TEXT(INDEX(KhoiVTM!$M:$M,MATCH(B15,KhoiVTM!$C:$C,0)),"@")="",TEXT(INDEX(KhoiVTM!$M:$M,MATCH(B15,KhoiVTM!$C:$C,0)),"@")="—")),EXACT(TEXT(E15,"@"),TEXT(INDEX(KhoiVTM!$M:$M,MATCH(B15,KhoiVTM!$C:$C,0)),"@"))),FALSE())*1)>=3,"Partial","Mismatch"))),"Not Found") -> Match
A16: =KhoiVTM!A16 -> 15 | B16: =KhoiVTM!C16 -> RC0603FR-0751RL | C16: =KhoiVTM!D16 -> RES 51 OHM 1% 1/10W 0603 | D16: 51 | E16: =RIGHT(TRIM(C16), 4) -> 0603 | F16: =KhoiVTM!F16 -> 25 | G16: 0 | H16: 0 | I16: =F16-H16 -> 25 | J16: =IF(LEFT(C16,3)="RES", "Resistor", IF(LEFT(C16,3)="CAP", "Capacitor", "Other")) -> Resistor | K16: Done | N16: =IFERROR(IF(ISERROR(MATCH(B16,KhoiVTM!$C:$C,0)),"Not Found",IF((EXACT(C16,IFERROR(INDEX(KhoiVTM!$D:$D,MATCH(B16,KhoiVTM!$C:$C,0)),"__NA__"))*1)+(IFERROR(F16=INDEX(KhoiVTM!$F:$F,MATCH(B16,KhoiVTM!$C:$C,0)),FALSE())*1)+(IFERROR(OR(AND(OR(D16="—",D16=""),OR(TEXT(INDEX(KhoiVTM!$J:$J,MATCH(B16,KhoiVTM!$C:$C,0)),"@")="",TEXT(INDEX(KhoiVTM!$J:$J,MATCH(B16,KhoiVTM!$C:$C,0)),"@")="—")),EXACT(TEXT(D16,"@"),TEXT(INDEX(KhoiVTM!$J:$J,MATCH(B16,KhoiVTM!$C:$C,0)),"@"))),FALSE())*1)+(IFERROR(OR(AND(OR(E16="—",E16=""),OR(TEXT(INDEX(KhoiVTM!$M:$M,MATCH(B16,KhoiVTM!$C:$C,0)),"@")="",TEXT(INDEX(KhoiVTM!$M:$M,MATCH(B16,KhoiVTM!$C:$C,0)),"@")="—")),EXACT(TEXT(E16,"@"),TEXT(INDEX(KhoiVTM!$M:$M,MATCH(B16,KhoiVTM!$C:$C,0)),"@"))),FALSE())*1)=4,"Match",IF((EXACT(C16,IFERROR(INDEX(KhoiVTM!$D:$D,MATCH(B16,KhoiVTM!$C:$C,0)),"__NA__"))*1)+(IFERROR(F16=INDEX(KhoiVTM!$F:$F,MATCH(B16,KhoiVTM!$C:$C,0)),FALSE())*1)+(IFERROR(OR(AND(OR(D16="—",D16=""),OR(TEXT(INDEX(KhoiVTM!$J:$J,MATCH(B16,KhoiVTM!$C:$C,0)),"@")="",TEXT(INDEX(KhoiVTM!$J:$J,MATCH(B16,KhoiVTM!$C:$C,0)),"@")="—")),EXACT(TEXT(D16,"@"),TEXT(INDEX(KhoiVTM!$J:$J,MATCH(B16,KhoiVTM!$C:$C,0)),"@"))),FALSE())*1)+(IFERROR(OR(AND(OR(E16="—",E16=""),OR(TEXT(INDEX(KhoiVTM!$M:$M,MATCH(B16,KhoiVTM!$C:$C,0)),"@")="",TEXT(INDEX(KhoiVTM!$M:$M,MATCH(B16,KhoiVTM!$C:$C,0)),"@")="—")),EXACT(TEXT(E16,"@"),TEXT(INDEX(KhoiVTM!$M:$M,MATCH(B16,KhoiVTM!$C:$C,0)),"@"))),FALSE())*1)>=3,"Partial","Mismatch"))),"Not Found") -> Match
A17: =KhoiVTM!A17 -> 16 | B17: =KhoiVTM!C17 -> RC0603FR-0710KL | C17: =KhoiVTM!D17 -> RES 10K OHM 1% 1/10W 0603 | D17: 10K | E17: =RIGHT(TRIM(C17), 4) -> 0603 | F17: =KhoiVTM!F17 -> 25 | G17: 8 | H17: 0 | I17: =F17-H17 -> 25 | J17: =IF(LEFT(C17,3)="RES", "Resistor", IF(LEFT(C17,3)="CAP", "Capacitor", "Other")) -> Resistor | K17: Done | N17: =IFERROR(IF(ISERROR(MATCH(B17,KhoiVTM!$C:$C,0)),"Not Found",IF((EXACT(C17,IFERROR(INDEX(KhoiVTM!$D:$D,MATCH(B17,KhoiVTM!$C:$C,0)),"__NA__"))*1)+(IFERROR(F17=INDEX(KhoiVTM!$F:$F,MATCH(B17,KhoiVTM!$C:$C,0)),FALSE())*1)+(IFERROR(OR(AND(OR(D17="—",D17=""),OR(TEXT(INDEX(KhoiVTM!$J:$J,MATCH(B17,KhoiVTM!$C:$C,0)),"@")="",TEXT(INDEX(KhoiVTM!$J:$J,MATCH(B17,KhoiVTM!$C:$C,0)),"@")="—")),EXACT(TEXT(D17,"@"),TEXT(INDEX(KhoiVTM!$J:$J,MATCH(B17,KhoiVTM!$C:$C,0)),"@"))),FALSE())*1)+(IFERROR(OR(AND(OR(E17="—",E17=""),OR(TEXT(INDEX(KhoiVTM!$M:$M,MATCH(B17,KhoiVTM!$C:$C,0)),"@")="",TEXT(INDEX(KhoiVTM!$M:$M,MATCH(B17,KhoiVTM!$C:$C,0)),"@")="—")),EXACT(TEXT(E17,"@"),TEXT(INDEX(KhoiVTM!$M:$M,MATCH(B17,KhoiVTM!$C:$C,0)),"@"))),FALSE())*1)=4,"Match",IF((EXACT(C17,IFERROR(INDEX(KhoiVTM!$D:$D,MATCH(B17,KhoiVTM!$C:$C,0)),"__NA__"))*1)+(IFERROR(F17=INDEX(KhoiVTM!$F:$F,MATCH(B17,KhoiVTM!$C:$C,0)),FALSE())*1)+(IFERROR(OR(AND(OR(D17="—",D17=""),OR(TEXT(INDEX(KhoiVTM!$J:$J,MATCH(B17,KhoiVTM!$C:$C,0)),"@")="",TEXT(INDEX(KhoiVTM!$J:$J,MATCH(B17,KhoiVTM!$C:$C,0)),"@")="—")),EXACT(TEXT(D17,"@"),TEXT(INDEX(KhoiVTM!$J:$J,MATCH(B17,KhoiVTM!$C:$C,0)),"@"))),FALSE())*1)+(IFERROR(OR(AND(OR(E17="—",E17=""),OR(TEXT(INDEX(KhoiVTM!$M:$M,MATCH(B17,KhoiVTM!$C:$C,0)),"@")="",TEXT(INDEX(KhoiVTM!$M:$M,MATCH(B17,KhoiVTM!$C:$C,0)),"@")="—")),EXACT(TEXT(E17,"@"),TEXT(INDEX(KhoiVTM!$M:$M,MATCH(B17,KhoiVTM!$C:$C,0)),"@"))),FALSE())*1)>=3,"Partial","Mismatch"))),"Not Found") -> Match
A18: =KhoiVTM!A18 -> 17 | B18: =KhoiVTM!C18 -> TNPW060310R0BEEA | C18: =KhoiVTM!D18 -> RES 10 OHM 0.1% 0.21W 0603 | D18: 10 | E18: =RIGHT(TRIM(C18), 4) -> 0603 | F18: =KhoiVTM!F18 -> 25 | G18: 0 | H18: 0 | I18: =F18-H18 -> 25 | J18: =IF(LEFT(C18,3)="RES", "Resistor", IF(LEFT(C18,3)="CAP", "Capacitor", "Other")) -> Resistor | K18: Done | N18: =IFERROR(IF(ISERROR(MATCH(B18,KhoiVTM!$C:$C,0)),"Not Found",IF((EXACT(C18,IFERROR(INDEX(KhoiVTM!$D:$D,MATCH(B18,KhoiVTM!$C:$C,0)),"__NA__"))*1)+(IFERROR(F18=INDEX(KhoiVTM!$F:$F,MATCH(B18,KhoiVTM!$C:$C,0)),FALSE())*1)+(IFERROR(OR(AND(OR(D18="—",D18=""),OR(TEXT(INDEX(KhoiVTM!$J:$J,MATCH(B18,KhoiVTM!$C:$C,0)),"@")="",TEXT(INDEX(KhoiVTM!$J:$J,MATCH(B18,KhoiVTM!$C:$C,0)),"@")="—")),EXACT(TEXT(D18,"@"),TEXT(INDEX(KhoiVTM!$J:$J,MATCH(B18,KhoiVTM!$C:$C,0)),"@"))),FALSE())*1)+(IFERROR(OR(AND(OR(E18="—",E18=""),OR(TEXT(INDEX(KhoiVTM!$M:$M,MATCH(B18,KhoiVTM!$C:$C,0)),"@")="",TEXT(INDEX(KhoiVTM!$M:$M,MATCH(B18,KhoiVTM!$C:$C,0)),"@")="—")),EXACT(TEXT(E18,"@"),TEXT(INDEX(KhoiVTM!$M:$M,MATCH(B18,KhoiVTM!$C:$C,0)),"@"))),FALSE())*1)=4,"Match",IF((EXACT(C18,IFERROR(INDEX(KhoiVTM!$D:$D,MATCH(B18,KhoiVTM!$C:$C,0)),"__NA__"))*1)+(IFERROR(F18=INDEX(KhoiVTM!$F:$F,MATCH(B18,KhoiVTM!$C:$C,0)),FALSE())*1)+(IFERROR(OR(AND(OR(D18="—",D18=""),OR(TEXT(INDEX(KhoiVTM!$J:$J,MATCH(B18,KhoiVTM!$C:$C,0)),"@")="",TEXT(INDEX(KhoiVTM!$J:$J,MATCH(B18,KhoiVTM!$C:$C,0)),"@")="—")),EXACT(TEXT(D18,"@"),TEXT(INDEX(KhoiVTM!$J:$J,MATCH(B18,KhoiVTM!$C:$C,0)),"@"))),FALSE())*1)+(IFERROR(OR(AND(OR(E18="—",E18=""),OR(TEXT(INDEX(KhoiVTM!$M:$M,MATCH(B18,KhoiVTM!$C:$C,0)),"@")="",TEXT(INDEX(KhoiVTM!$M:$M,MATCH(B18,KhoiVTM!$C:$C,0)),"@")="—")),EXACT(TEXT(E18,"@"),TEXT(INDEX(KhoiVTM!$M:$M,MATCH(B18,KhoiVTM!$C:$C,0)),"@"))),FALSE())*1)>=3,"Partial","Mismatch"))),"Not Found") -> Match
A19: =KhoiVTM!A19 -> 18 | B19: =KhoiVTM!C19 -> GRM1885C1H200JA01D | C19: =KhoiVTM!D19 -> CAP CER 20PF 50V C0G/NP0 0603 | D19: 20P | E19: =RIGHT(TRIM(C19), 4) -> 0603 | F19: =KhoiVTM!F19 -> 25 | G19: 2 | H19: 0 | I19: =F19-H19 -> 25 | J19: =IF(LEFT(C19,3)="RES", "Resistor", IF(LEFT(C19,3)="CAP", "Capacitor", "Other")) -> Capacitor | K19: Done | N19: =IFERROR(IF(ISERROR(MATCH(B19,KhoiVTM!$C:$C,0)),"Not Found",IF((EXACT(C19,IFERROR(INDEX(KhoiVTM!$D:$D,MATCH(B19,KhoiVTM!$C:$C,0)),"__NA__"))*1)+(IFERROR(F19=INDEX(KhoiVTM!$F:$F,MATCH(B19,KhoiVTM!$C:$C,0)),FALSE())*1)+(IFERROR(OR(AND(OR(D19="—",D19=""),OR(TEXT(INDEX(KhoiVTM!$J:$J,MATCH(B19,KhoiVTM!$C:$C,0)),"@")="",TEXT(INDEX(KhoiVTM!$J:$J,MATCH(B19,KhoiVTM!$C:$C,0)),"@")="—")),EXACT(TEXT(D19,"@"),TEXT(INDEX(KhoiVTM!$J:$J,MATCH(B19,KhoiVTM!$C:$C,0)),"@"))),FALSE())*1)+(IFERROR(OR(AND(OR(E19="—",E19=""),OR(TEXT(INDEX(KhoiVTM!$M:$M,MATCH(B19,KhoiVTM!$C:$C,0)),"@")="",TEXT(INDEX(KhoiVTM!$M:$M,MATCH(B19,KhoiVTM!$C:$C,0)),"@")="—")),EXACT(TEXT(E19,"@"),TEXT(INDEX(KhoiVTM!$M:$M,MATCH(B19,KhoiVTM!$C:$C,0)),"@"))),FALSE())*1)=4,"Match",IF((EXACT(C19,IFERROR(INDEX(KhoiVTM!$D:$D,MATCH(B19,KhoiVTM!$C:$C,0)),"__NA__"))*1)+(IFERROR(F19=INDEX(KhoiVTM!$F:$F,MATCH(B19,KhoiVTM!$C:$C,0)),FALSE())*1)+(IFERROR(OR(AND(OR(D19="—",D19=""),OR(TEXT(INDEX(KhoiVTM!$J:$J,MATCH(B19,KhoiVTM!$C:$C,0)),"@")="",TEXT(INDEX(KhoiVTM!$J:$J,MATCH(B19,KhoiVTM!$C:$C,0)),"@")="—")),EXACT(TEXT(D19,"@"),TEXT(INDEX(KhoiVTM!$J:$J,MATCH(B19,KhoiVTM!$C:$C,0)),"@"))),FALSE())*1)+(IFERROR(OR(AND(OR(E19="—",E19=""),OR(TEXT(INDEX(KhoiVTM!$M:$M,MATCH(B19,KhoiVTM!$C:$C,0)),"@")="",TEXT(INDEX(KhoiVTM!$M:$M,MATCH(B19,KhoiVTM!$C:$C,0)),"@")="—")),EXACT(TEXT(E19,"@"),TEXT(INDEX(KhoiVTM!$M:$M,MATCH(B19,KhoiVTM!$C:$C,0)),"@"))),FALSE())*1)>=3,"Partial","Mismatch"))),"Not Found") -> Match
A20: =KhoiVTM!A20 -> 19 | B20: =KhoiVTM!C20 -> GRM155R71H104KE14D | C20: =KhoiVTM!D20 -> CAP CER 0.1UF 50V X7R 0603 | D20: 0.1U | E20: =RIGHT(TRIM(C20), 4) -> 0603 | F20: =KhoiVTM!F20 -> 25 | G20: 27 | H20: 0 | I20: =F20-H20 -> 25 | J20: =IF(LEFT(C20,3)="RES", "Resistor", IF(LEFT(C20,3)="CAP", "Capacitor", "Other")) -> Capacitor | K20: Done | N20: =IFERROR(IF(ISERROR(MATCH(B20,KhoiVTM!$C:$C,0)),"Not Found",IF((EXACT(C20,IFERROR(INDEX(KhoiVTM!$D:$D,MATCH(B20,KhoiVTM!$C:$C,0)),"__NA__"))*1)+(IFERROR(F20=INDEX(KhoiVTM!$F:$F,MATCH(B20,KhoiVTM!$C:$C,0)),FALSE())*1)+(IFERROR(OR(AND(OR(D20="—",D20=""),OR(TEXT(INDEX(KhoiVTM!$J:$J,MATCH(B20,KhoiVTM!$C:$C,0)),"@")="",TEXT(INDEX(KhoiVTM!$J:$J,MATCH(B20,KhoiVTM!$C:$C,0)),"@")="—")),EXACT(TEXT(D20,"@"),TEXT(INDEX(KhoiVTM!$J:$J,MATCH(B20,KhoiVTM!$C:$C,0)),"@"))),FALSE())*1)+(IFERROR(OR(AND(OR(E20="—",E20=""),OR(TEXT(INDEX(KhoiVTM!$M:$M,MATCH(B20,KhoiVTM!$C:$C,0)),"@")="",TEXT(INDEX(KhoiVTM!$M:$M,MATCH(B20,KhoiVTM!$C:$C,0)),"@")="—")),EXACT(TEXT(E20,"@"),TEXT(INDEX(KhoiVTM!$M:$M,MATCH(B20,KhoiVTM!$C:$C,0)),"@"))),FALSE())*1)=4,"Match",IF((EXACT(C20,IFERROR(INDEX(KhoiVTM!$D:$D,MATCH(B20,KhoiVTM!$C:$C,0)),"__NA__"))*1)+(IFERROR(F20=INDEX(KhoiVTM!$F:$F,MATCH(B20,KhoiVTM!$C:$C,0)),FALSE())*1)+(IFERROR(OR(AND(OR(D20="—",D20=""),OR(TEXT(INDEX(KhoiVTM!$J:$J,MATCH(B20,KhoiVTM!$C:$C,0)),"@")="",TEXT(INDEX(KhoiVTM!$J:$J,MATCH(B20,KhoiVTM!$C:$C,0)),"@")="—")),EXACT(TEXT(D20,"@"),TEXT(INDEX(KhoiVTM!$J:$J,MATCH(B20,KhoiVTM!$C:$C,0)),"@"))),FALSE())*1)+(IFERROR(OR(AND(OR(E20="—",E20=""),OR(TEXT(INDEX(KhoiVTM!$M:$M,MATCH(B20,KhoiVTM!$C:$C,0)),"@")="",TEXT(INDEX(KhoiVTM!$M:$M,MATCH(B20,KhoiVTM!$C:$C,0)),"@")="—")),EXACT(TEXT(E20,"@"),TEXT(INDEX(KhoiVTM!$M:$M,MATCH(B20,KhoiVTM!$C:$C,0)),"@"))),FALSE())*1)>=3,"Partial","Mismatch"))),"Not Found") -> Match
A21: =KhoiVTM!A21 -> 20 | B21: =KhoiVTM!C21 -> C0603C105K3RACTU | C21: =KhoiVTM!D21 -> CAP CER 1UF 25V X7R 0603 | D21: 1U | E21: =RIGHT(TRIM(C21), 4) -> 0603 | F21: =KhoiVTM!F21 -> 25 | G21: 0 | H21: 0 | I21: =F21-H21 -> 25 | J21: =IF(LEFT(C21,3)="RES", "Resistor", IF(LEFT(C21,3)="CAP", "Capacitor", "Other")) -> Capacitor | K21: Done | N21: =IFERROR(IF(ISERROR(MATCH(B21,KhoiVTM!$C:$C,0)),"Not Found",IF((EXACT(C21,IFERROR(INDEX(KhoiVTM!$D:$D,MATCH(B21,KhoiVTM!$C:$C,0)),"__NA__"))*1)+(IFERROR(F21=INDEX(KhoiVTM!$F:$F,MATCH(B21,KhoiVTM!$C:$C,0)),FALSE())*1)+(IFERROR(OR(AND(OR(D21="—",D21=""),OR(TEXT(INDEX(KhoiVTM!$J:$J,MATCH(B21,KhoiVTM!$C:$C,0)),"@")="",TEXT(INDEX(KhoiVTM!$J:$J,MATCH(B21,KhoiVTM!$C:$C,0)),"@")="—")),EXACT(TEXT(D21,"@"),TEXT(INDEX(KhoiVTM!$J:$J,MATCH(B21,KhoiVTM!$C:$C,0)),"@"))),FALSE())*1)+(IFERROR(OR(AND(OR(E21="—",E21=""),OR(TEXT(INDEX(KhoiVTM!$M:$M,MATCH(B21,KhoiVTM!$C:$C,0)),"@")="",TEXT(INDEX(KhoiVTM!$M:$M,MATCH(B21,KhoiVTM!$C:$C,0)),"@")="—")),EXACT(TEXT(E21,"@"),TEXT(INDEX(KhoiVTM!$M:$M,MATCH(B21,KhoiVTM!$C:$C,0)),"@"))),FALSE())*1)=4,"Match",IF((EXACT(C21,IFERROR(INDEX(KhoiVTM!$D:$D,MATCH(B21,KhoiVTM!$C:$C,0)),"__NA__"))*1)+(IFERROR(F21=INDEX(KhoiVTM!$F:$F,MATCH(B21,KhoiVTM!$C:$C,0)),FALSE())*1)+(IFERROR(OR(AND(OR(D21="—",D21=""),OR(TEXT(INDEX(KhoiVTM!$J:$J,MATCH(B21,KhoiVTM!$C:$C,0)),"@")="",TEXT(INDEX(KhoiVTM!$J:$J,MATCH(B21,KhoiVTM!$C:$C,0)),"@")="—")),EXACT(TEXT(D21,"@"),TEXT(INDEX(KhoiVTM!$J:$J,MATCH(B21,KhoiVTM!$C:$C,0)),"@"))),FALSE())*1)+(IFERROR(OR(AND(OR(E21="—",E21=""),OR(TEXT(INDEX(KhoiVTM!$M:$M,MATCH(B21,KhoiVTM!$C:$C,0)),"@")="",TEXT(INDEX(KhoiVTM!$M:$M,MATCH(B21,KhoiVTM!$C:$C,0)),"@")="—")),EXACT(TEXT(E21,"@"),TEXT(INDEX(KhoiVTM!$M:$M,MATCH(B21,KhoiVTM!$C:$C,0)),"@"))),FALSE())*1)>=3,"Partial","Mismatch"))),"Not Found") -> Match
A22: =KhoiVTM!A22 -> 21 | B22: =KhoiVTM!C22 -> GRM1555C1H1R0WA01J | C22: =KhoiVTM!D22 -> CAP CER 1PF 50V C0G/NP0 0402 | D22: 1P | E22: =RIGHT(TRIM(C22), 4) -> 0402 | F22: =KhoiVTM!F22 -> 25 | G22: 0 | H22: 0 | I22: =F22-H22 -> 25 | J22: =IF(LEFT(C22,3)="RES", "Resistor", IF(LEFT(C22,3)="CAP", "Capacitor", "Other")) -> Capacitor | K22: Done | N22: =IFERROR(IF(ISERROR(MATCH(B22,KhoiVTM!$C:$C,0)),"Not Found",IF((EXACT(C22,IFERROR(INDEX(KhoiVTM!$D:$D,MATCH(B22,KhoiVTM!$C:$C,0)),"__NA__"))*1)+(IFERROR(F22=INDEX(KhoiVTM!$F:$F,MATCH(B22,KhoiVTM!$C:$C,0)),FALSE())*1)+(IFERROR(OR(AND(OR(D22="—",D22=""),OR(TEXT(INDEX(KhoiVTM!$J:$J,MATCH(B22,KhoiVTM!$C:$C,0)),"@")="",TEXT(INDEX(KhoiVTM!$J:$J,MATCH(B22,KhoiVTM!$C:$C,0)),"@")="—")),EXACT(TEXT(D22,"@"),TEXT(INDEX(KhoiVTM!$J:$J,MATCH(B22,KhoiVTM!$C:$C,0)),"@"))),FALSE())*1)+(IFERROR(OR(AND(OR(E22="—",E22=""),OR(TEXT(INDEX(KhoiVTM!$M:$M,MATCH(B22,KhoiVTM!$C:$C,0)),"@")="",TEXT(INDEX(KhoiVTM!$M:$M,MATCH(B22,KhoiVTM!$C:$C,0)),"@")="—")),EXACT(TEXT(E22,"@"),TEXT(INDEX(KhoiVTM!$M:$M,MATCH(B22,KhoiVTM!$C:$C,0)),"@"))),FALSE())*1)=4,"Match",IF((EXACT(C22,IFERROR(INDEX(KhoiVTM!$D:$D,MATCH(B22,KhoiVTM!$C:$C,0)),"__NA__"))*1)+(IFERROR(F22=INDEX(KhoiVTM!$F:$F,MATCH(B22,KhoiVTM!$C:$C,0)),FALSE())*1)+(IFERROR(OR(AND(OR(D22="—",D22=""),OR(TEXT(INDEX(KhoiVTM!$J:$J,MATCH(B22,KhoiVTM!$C:$C,0)),"@")="",TEXT(INDEX(KhoiVTM!$J:$J,MATCH(B22,KhoiVTM!$C:$C,0)),"@")="—")),EXACT(TEXT(D22,"@"),TEXT(INDEX(KhoiVTM!$J:$J,MATCH(B22,KhoiVTM!$C:$C,0)),"@"))),FALSE())*1)+(IFERROR(OR(AND(OR(E22="—",E22=""),OR(TEXT(INDEX(KhoiVTM!$M:$M,MATCH(B22,KhoiVTM!$C:$C,0)),"@")="",TEXT(INDEX(KhoiVTM!$M:$M,MATCH(B22,KhoiVTM!$C:$C,0)),"@")="—")),EXACT(TEXT(E22,"@"),TEXT(INDEX(KhoiVTM!$M:$M,MATCH(B22,KhoiVTM!$C:$C,0)),"@"))),FALSE())*1)>=3,"Partial","Mismatch"))),"Not Found") -> Match
A23: =KhoiVTM!A23 -> 22 | B23: =KhoiVTM!C23 -> CC0805KKX5R9BB225 | C23: =KhoiVTM!D23 -> CAP CER 2.2UF 50V X5R 0805 | D23: 2.2U | E23: =RIGHT(TRIM(C23), 4) -> 0805 | F23: =KhoiVTM!F23 -> 25 | G23: 0 | H23: 0 | I23: =F23-H23 -> 25 | J23: =IF(LEFT(C23,3)="RES", "Resistor", IF(LEFT(C23,3)="CAP", "Capacitor", "Other")) -> Capacitor | K23: Done | N23: =IFERROR(IF(ISERROR(MATCH(B23,KhoiVTM!$C:$C,0)),"Not Found",IF((EXACT(C23,IFERROR(INDEX(KhoiVTM!$D:$D,MATCH(B23,KhoiVTM!$C:$C,0)),"__NA__"))*1)+(IFERROR(F23=INDEX(KhoiVTM!$F:$F,MATCH(B23,KhoiVTM!$C:$C,0)),FALSE())*1)+(IFERROR(OR(AND(OR(D23="—",D23=""),OR(TEXT(INDEX(KhoiVTM!$J:$J,MATCH(B23,KhoiVTM!$C:$C,0)),"@")="",TEXT(INDEX(KhoiVTM!$J:$J,MATCH(B23,KhoiVTM!$C:$C,0)),"@")="—")),EXACT(TEXT(D23,"@"),TEXT(INDEX(KhoiVTM!$J:$J,MATCH(B23,KhoiVTM!$C:$C,0)),"@"))),FALSE())*1)+(IFERROR(OR(AND(OR(E23="—",E23=""),OR(TEXT(INDEX(KhoiVTM!$M:$M,MATCH(B23,KhoiVTM!$C:$C,0)),"@")="",TEXT(INDEX(KhoiVTM!$M:$M,MATCH(B23,KhoiVTM!$C:$C,0)),"@")="—")),EXACT(TEXT(E23,"@"),TEXT(INDEX(KhoiVTM!$M:$M,MATCH(B23,KhoiVTM!$C:$C,0)),"@"))),FALSE())*1)=4,"Match",IF((EXACT(C23,IFERROR(INDEX(KhoiVTM!$D:$D,MATCH(B23,KhoiVTM!$C:$C,0)),"__NA__"))*1)+(IFERROR(F23=INDEX(KhoiVTM!$F:$F,MATCH(B23,KhoiVTM!$C:$C,0)),FALSE())*1)+(IFERROR(OR(AND(OR(D23="—",D23=""),OR(TEXT(INDEX(KhoiVTM!$J:$J,MATCH(B23,KhoiVTM!$C:$C,0)),"@")="",TEXT(INDEX(KhoiVTM!$J:$J,MATCH(B23,KhoiVTM!$C:$C,0)),"@")="—")),EXACT(TEXT(D23,"@"),TEXT(INDEX(KhoiVTM!$J:$J,MATCH(B23,KhoiVTM!$C:$C,0)),"@"))),FALSE())*1)+(IFERROR(OR(AND(OR(E23="—",E23=""),OR(TEXT(INDEX(KhoiVTM!$M:$M,MATCH(B23,KhoiVTM!$C:$C,0)),"@")="",TEXT(INDEX(KhoiVTM!$M:$M,MATCH(B23,KhoiVTM!$C:$C,0)),"@")="—")),EXACT(TEXT(E23,"@"),TEXT(INDEX(KhoiVTM!$M:$M,MATCH(B23,KhoiVTM!$C:$C,0)),"@"))),FALSE())*1)>=3,"Partial","Mismatch"))),"Not Found") -> Match
